Workbook
Name aa: #REF!
Name ABDERA_: #REF!
Name ACABAMENTO_: #REF!
Name ACACIA_: #REF!
Name ACCOR_: #REF!
Name ADANA_: #REF!
Name AF_general: #REF!
Name AFTONE_: #REF!
Name AGHATA_: #REF!
Name ALAMO_: #REF!
Name ÁLAVA_: #REF!
Name ALINA_: #REF!
Name ALLADRO_: #REF!
Name ALLEGRO_: #REF!
Name ALLURE_: #REF!
Name ALMADA_: #REF!
Name ALMOFADA_: #REF!
Name AMALFI_: #REF!
Name AMAZONAS_: #REF!
Name AMELIA_: #REF!
Name ANCONA_: #REF!
Name ANDRIA_: #REF!
Name ANDROS_: #REF!
Name ANTARES_: #REF!
Name ARAGUAIA_: #REF!
Name ARAMIS_: #REF!
Name AREZZO_: #REF!
Name ARGOS_: #REF!
Name ARMANY_: #REF!
Name ARMENIA_: #REF!
Name ARROYOS_: #REF!
Name ARTTIS_: #REF!
Name ARTTIS_CAMA_: #REF!
Name ASIA_: #REF!
Name ASSUNÇÃO_: #REF!
Name ASTON_: #REF!
Name ASTOR_: #REF!
Name ASTORY_: #REF!
Name ASTURIAS_: #REF!
Name ASUNCION_: #REF!
Name ATHENAS_: #REF!
Name ATILA_: #REF!
Name ATLAS_: #REF!
Name ATRANI_: #REF!
Name AUSTRIA_: #REF!
Name BACCUS_: #REF!
Name BAEZA_: #REF!
Name BANCO_AMATRICE_: #REF!
Name BANCO_BERNARDINO_: #REF!
Name BANCO_DALI_: #REF!
Name BANCO_GRAZ_: #REF!
Name BANCO_KANOPE_: #REF!
Name BANCO_NEW_: #REF!
Name BANCO_VELDE_: #REF!
Name BANCO_VERNASA_: #REF!
Name BARRAGAN_: #REF!
Name BARROMINI_: #REF!
Name BAUHAUS_: #REF!
Name bb: #REF!
Name BEDFORD_: #REF!

Sheet CAPA
A1: Tabela de Preço de Venda
A12: PRAZO MÉDIO DE PAGAMENTO | B12: 15 DIAS - OURO
A14: MARKUP LOJISTA | B14: 1
A31: FRETE: FOB
A32: PRAZO DE ENTREGA: 50 DIAS
A33: PRAZO DE ENTREGA E/: ATÉ 65 DIAS
A35: OBSERVAÇÕES:
A36: *MEDIDAS ESPECIAIS: SEMPRE MEDIANTE APROVAÇÃO DA INDUSTRIA;
A37: *PRATO GIRATÓRIO EM MESAS REDONDAS: ACRÉSCIMO DE 10% NO VALOR DO ACABAMENTO ESCOLHIDO; | L37: Versão:0001
A38: *EM CASO DE ASSITÊNCIA TÉCNICA, ENTRAR EM CONTATO COM O REPRESENTANTE COMERCIAL DE SUA REGIÃO; | L38: Atualização: 22/01/2026

Sheet APARADOR
B2: TABELA DE PREÇO CENTURY | MADEIRA
C5: Dimensoes (metros)
A6: Imagem | B6: Nome | C6: C | D6: L | E6: A | G6: Tampo: Espelho Bronze, Fume, Prata, Vidro Fosco ou Clear Corpo: Laca ou Lamina | H6: Tampo: Laca ou Lamina com ou sem Vidro Normal Pintado Corpo: Laca ou Lamina | I6: Tampo: Mármore Especial Corpo: Laca ou Lamina | J6: Tampo: Mármore Normal Corpo: Laca ou Lamina | K6: Tampo ou Base em Recoro
B7: Sienna Aparador - 1.4x0.45x0.75 - Acabamentos Customizados | C7: 1.4 | D7: 0.45 | E7: 0.75 | G7: =IFERROR(IF('BASE DE DADOS PREÇOS'!$M$71="com",VLOOKUP(CONCATENATE(B7,$G$6),'BASE DE DADOS PREÇOS'!$E:$H,4,0)/(1-SUM($F$1))*VLOOKUP(CAPA!$B$12,'POLITICA DE PREÇO'!#REF!,2,0)*0.95,VLOOKUP(CONCATENATE(B7,$G$6),'BASE DE DADOS PREÇOS'!$E:$H,4,0)/(1-SUM($F$1))*VLOOKUP(CAPA!$B$12,'POLITICA DE PREÇO'!$B$4:$F$100,5,0))*CAPA!$B$14,"") -> 3254.8243 | H7: =IFERROR(IF('BASE DE DADOS PREÇOS'!$M$71="com",VLOOKUP(CONCATENATE(B7,$H$6),'BASE DE DADOS PREÇOS'!$E:$H,4,0)/(1-SUM($F$1))*VLOOKUP(CAPA!$B$12,'POLITICA DE PREÇO'!#REF!,2,0)*0.95,VLOOKUP(CONCATENATE(B7,$H$6),'BASE DE DADOS PREÇOS'!$E:$H,4,0)/(1-SUM($F$1))*VLOOKUP(CAPA!$B$12,'POLITICA DE PREÇO'!$B$4:$F$100,5,0))*CAPA!$B$14,"") -> 2640.8313 | I7: =IFERROR(IF('BASE DE DADOS PREÇOS'!$M$71="com",VLOOKUP(CONCATENATE(B7,$I$6),'BASE DE DADOS PREÇOS'!$E:$H,4,0)/(1-SUM($F$1))*VLOOKUP(CAPA!$B$12,'POLITICA DE PREÇO'!#REF!,2,0)*0.95,VLOOKUP(CONCATENATE(B7,$I$6),'BASE DE DADOS PREÇOS'!$E:$H,4,0)/(1-SUM($F$1))*VLOOKUP(CAPA!$B$12,'POLITICA DE PREÇO'!$B$4:$F$100,5,0))*CAPA!$B$14,"") -> 5550.635 | J7: =I7*0.9 -> 4995.5715 | K7: =H7*1.05 -> 2772.8729
B8: Sienna Aparador - 1.6x0.45x0.75 - Acabamentos Customizados | C8: 1.6 | D8: 0.45 | E8: 0.75 | G8: =IFERROR(IF('BASE DE DADOS PREÇOS'!$M$71="com",VLOOKUP(CONCATENATE(B8,$G$6),'BASE DE DADOS PREÇOS'!$E:$H,4,0)/(1-SUM($F$1))*VLOOKUP(CAPA!$B$12,'POLITICA DE PREÇO'!#REF!,2,0)*0.95,VLOOKUP(CONCATENATE(B8,$G$6),'BASE DE DADOS PREÇOS'!$E:$H,4,0)/(1-SUM($F$1))*VLOOKUP(CAPA!$B$12,'POLITICA DE PREÇO'!$B$4:$F$100,5,0))*CAPA!$B$14,"") -> 3719.7992 | H8: =IFERROR(IF('BASE DE DADOS PREÇOS'!$M$71="com",VLOOKUP(CONCATENATE(B8,$H$6),'BASE DE DADOS PREÇOS'!$E:$H,4,0)/(1-SUM($F$1))*VLOOKUP(CAPA!$B$12,'POLITICA DE PREÇO'!#REF!,2,0)*0.95,VLOOKUP(CONCATENATE(B8,$H$6),'BASE DE DADOS PREÇOS'!$E:$H,4,0)/(1-SUM($F$1))*VLOOKUP(CAPA!$B$12,'POLITICA DE PREÇO'!$B$4:$F$100,5,0))*CAPA!$B$14,"") -> 3018.093 | I8: =IFERROR(IF('BASE DE DADOS PREÇOS'!$M$71="com",VLOOKUP(CONCATENATE(B8,$I$6),'BASE DE DADOS PREÇOS'!$E:$H,4,0)/(1-SUM($F$1))*VLOOKUP(CAPA!$B$12,'POLITICA DE PREÇO'!#REF!,2,0)*0.95,VLOOKUP(CONCATENATE(B8,$I$6),'BASE DE DADOS PREÇOS'!$E:$H,4,0)/(1-SUM($F$1))*VLOOKUP(CAPA!$B$12,'POLITICA DE PREÇO'!$B$4:$F$100,5,0))*CAPA!$B$14,"") -> 6343.5829 | J8: =I8*0.9 -> 5709.2246 | K8: =H8*1.05 -> 3168.9976
B9: Sienna Aparador - 1.8x0.45x0.75 - Acabamentos Customizados | C9: 1.8 | D9: 0.45 | E9: 0.75 | G9: =IFERROR(IF('BASE DE DADOS PREÇOS'!$M$71="com",VLOOKUP(CONCATENATE(B9,$G$6),'BASE DE DADOS PREÇOS'!$E:$H,4,0)/(1-SUM($F$1))*VLOOKUP(CAPA!$B$12,'POLITICA DE PREÇO'!#REF!,2,0)*0.95,VLOOKUP(CONCATENATE(B9,$G$6),'BASE DE DADOS PREÇOS'!$E:$H,4,0)/(1-SUM($F$1))*VLOOKUP(CAPA!$B$12,'POLITICA DE PREÇO'!$B$4:$F$100,5,0))*CAPA!$B$14,"") -> 4184.7741 | H9: =IFERROR(IF('BASE DE DADOS PREÇOS'!$M$71="com",VLOOKUP(CONCATENATE(B9,$H$6),'BASE DE DADOS PREÇOS'!$E:$H,4,0)/(1-SUM($F$1))*VLOOKUP(CAPA!$B$12,'POLITICA DE PREÇO'!#REF!,2,0)*0.95,VLOOKUP(CONCATENATE(B9,$H$6),'BASE DE DADOS PREÇOS'!$E:$H,4,0)/(1-SUM($F$1))*VLOOKUP(CAPA!$B$12,'POLITICA DE PREÇO'!$B$4:$F$100,5,0))*CAPA!$B$14,"") -> 3395.3546 | I9: =IFERROR(IF('BASE DE DADOS PREÇOS'!$M$71="com",VLOOKUP(CONCATENATE(B9,$I$6),'BASE DE DADOS PREÇOS'!$E:$H,4,0)/(1-SUM($F$1))*VLOOKUP(CAPA!$B$12,'POLITICA DE PREÇO'!#REF!,2,0)*0.95,VLOOKUP(CONCATENATE(B9,$I$6),'BASE DE DADOS PREÇOS'!$E:$H,4,0)/(1-SUM($F$1))*VLOOKUP(CAPA!$B$12,'POLITICA DE PREÇO'!$B$4:$F$100,5,0))*CAPA!$B$14,"") -> 7136.5308 | J9: =I9*0.9 -> 6422.8777 | K9: =H9*1.05 -> 3565.1223
B10: Sienna Aparador - 2x0.45x0.75 - Acabamentos Customizados | C10: 2 | D10: 0.45 | E10: 0.75 | G10: =IFERROR(IF('BASE DE DADOS PREÇOS'!$M$71="com",VLOOKUP(CONCATENATE(B10,$G$6),'BASE DE DADOS PREÇOS'!$E:$H,4,0)/(1-SUM($F$1))*VLOOKUP(CAPA!$B$12,'POLITICA DE PREÇO'!#REF!,2,0)*0.95,VLOOKUP(CONCATENATE(B10,$G$6),'BASE DE DADOS PREÇOS'!$E:$H,4,0)/(1-SUM($F$1))*VLOOKUP(CAPA!$B$12,'POLITICA DE PREÇO'!$B$4:$F$100,5,0))*CAPA!$B$14,"") -> 4649.749 | H10: =IFERROR(IF('BASE DE DADOS PREÇOS'!$M$71="com",VLOOKUP(CONCATENATE(B10,$H$6),'BASE DE DADOS PREÇOS'!$E:$H,4,0)/(1-SUM($F$1))*VLOOKUP(CAPA!$B$12,'POLITICA DE PREÇO'!#REF!,2,0)*0.95,VLOOKUP(CONCATENATE(B10,$H$6),'BASE DE DADOS PREÇOS'!$E:$H,4,0)/(1-SUM($F$1))*VLOOKUP(CAPA!$B$12,'POLITICA DE PREÇO'!$B$4:$F$100,5,0))*CAPA!$B$14,"") -> 3772.6162 | I10: =IFERROR(IF('BASE DE DADOS PREÇOS'!$M$71="com",VLOOKUP(CONCATENATE(B10,$I$6),'BASE DE DADOS PREÇOS'!$E:$H,4,0)/(1-SUM($F$1))*VLOOKUP(CAPA!$B$12,'POLITICA DE PREÇO'!#REF!,2,0)*0.95,VLOOKUP(CONCATENATE(B10,$I$6),'BASE DE DADOS PREÇOS'!$E:$H,4,0)/(1-SUM($F$1))*VLOOKUP(CAPA!$B$12,'POLITICA DE PREÇO'!$B$4:$F$100,5,0))*CAPA!$B$14,"") -> 7929.4786 | J10: =I10*0.9 -> 7136.5308 | K10: =H10*1.05 -> 3961.247
B11: Sienna Aparador - 2.2x0.45x0.75 - Acabamentos Customizados | C11: 2.2 | D11: 0.45 | E11: 0.75 | G11: =IFERROR(IF('BASE DE DADOS PREÇOS'!$M$71="com",VLOOKUP(CONCATENATE(B11,$G$6),'BASE DE DADOS PREÇOS'!$E:$H,4,0)/(1-SUM($F$1))*VLOOKUP(CAPA!$B$12,'POLITICA DE PREÇO'!#REF!,2,0)*0.95,VLOOKUP(CONCATENATE(B11,$G$6),'BASE DE DADOS PREÇOS'!$E:$H,4,0)/(1-SUM($F$1))*VLOOKUP(CAPA!$B$12,'POLITICA DE PREÇO'!$B$4:$F$100,5,0))*CAPA!$B$14,"") -> 5114.7239 | H11: =IFERROR(IF('BASE DE DADOS PREÇOS'!$M$71="com",VLOOKUP(CONCATENATE(B11,$H$6),'BASE DE DADOS PREÇOS'!$E:$H,4,0)/(1-SUM($F$1))*VLOOKUP(CAPA!$B$12,'POLITICA DE PREÇO'!#REF!,2,0)*0.95,VLOOKUP(CONCATENATE(B11,$H$6),'BASE DE DADOS PREÇOS'!$E:$H,4,0)/(1-SUM($F$1))*VLOOKUP(CAPA!$B$12,'POLITICA DE PREÇO'!$B$4:$F$100,5,0))*CAPA!$B$14,"") -> 4149.8778 | I11: =IFERROR(IF('BASE DE DADOS PREÇOS'!$M$71="com",VLOOKUP(CONCATENATE(B11,$I$6),'BASE DE DADOS PREÇOS'!$E:$H,4,0)/(1-SUM($F$1))*VLOOKUP(CAPA!$B$12,'POLITICA DE PREÇO'!#REF!,2,0)*0.95,VLOOKUP(CONCATENATE(B11,$I$6),'BASE DE DADOS PREÇOS'!$E:$H,4,0)/(1-SUM($F$1))*VLOOKUP(CAPA!$B$12,'POLITICA DE PREÇO'!$B$4:$F$100,5,0))*CAPA!$B$14,"") -> 8722.4265 | J11: =I11*0.9 -> 7850.1839 | K11: =H11*1.05 -> 4357.3717
B12: Sienna Aparador - 2.4x0.45x0.75 - Acabamentos Customizados | C12: 2.4 | D12: 0.45 | E12: 0.75 | G12: =IFERROR(IF('BASE DE DADOS PREÇOS'!$M$71="com",VLOOKUP(CONCATENATE(B12,$G$6),'BASE DE DADOS PREÇOS'!$E:$H,4,0)/(1-SUM($F$1))*VLOOKUP(CAPA!$B$12,'POLITICA DE PREÇO'!#REF!,2,0)*0.95,VLOOKUP(CONCATENATE(B12,$G$6),'BASE DE DADOS PREÇOS'!$E:$H,4,0)/(1-SUM($F$1))*VLOOKUP(CAPA!$B$12,'POLITICA DE PREÇO'!$B$4:$F$100,5,0))*CAPA!$B$14,"") -> 5579.6988 | H12: =IFERROR(IF('BASE DE DADOS PREÇOS'!$M$71="com",VLOOKUP(CONCATENATE(B12,$H$6),'BASE DE DADOS PREÇOS'!$E:$H,4,0)/(1-SUM($F$1))*VLOOKUP(CAPA!$B$12,'POLITICA DE PREÇO'!#REF!,2,0)*0.95,VLOOKUP(CONCATENATE(B12,$H$6),'BASE DE DADOS PREÇOS'!$E:$H,4,0)/(1-SUM($F$1))*VLOOKUP(CAPA!$B$12,'POLITICA DE PREÇO'!$B$4:$F$100,5,0))*CAPA!$B$14,"") -> 4527.1395 | I12: =IFERROR(IF('BASE DE DADOS PREÇOS'!$M$71="com",VLOOKUP(CONCATENATE(B12,$I$6),'BASE DE DADOS PREÇOS'!$E:$H,4,0)/(1-SUM($F$1))*VLOOKUP(CAPA!$B$12,'POLITICA DE PREÇO'!#REF!,2,0)*0.95,VLOOKUP(CONCATENATE(B12,$I$6),'BASE DE DADOS PREÇOS'!$E:$H,4,0)/(1-SUM($F$1))*VLOOKUP(CAPA!$B$12,'POLITICA DE PREÇO'!$B$4:$F$100,5,0))*CAPA!$B$14,"") -> 9515.3744 | J12: =I12*0.9 -> 8563.8369 | K12: =H12*1.05 -> 4753.4964
B13: Taijin Aparador - 1.6x0.5x0.79 - Acabamentos Customizados | C13: 1.6 | D13: 0.5 | E13: 0.79 | G13: =IFERROR(IF('BASE DE DADOS PREÇOS'!$M$71="com",VLOOKUP(CONCATENATE(B13,$G$6),'BASE DE DADOS PREÇOS'!$E:$H,4,0)/(1-SUM($F$1))*VLOOKUP(CAPA!$B$12,'POLITICA DE PREÇO'!#REF!,2,0)*0.95,VLOOKUP(CONCATENATE(B13,$G$6),'BASE DE DADOS PREÇOS'!$E:$H,4,0)/(1-SUM($F$1))*VLOOKUP(CAPA!$B$12,'POLITICA DE PREÇO'!$B$4:$F$100,5,0))*CAPA!$B$14,"") -> 4589.4646 | H13: =IFERROR(IF('BASE DE DADOS PREÇOS'!$M$71="com",VLOOKUP(CONCATENATE(B13,$H$6),'BASE DE DADOS PREÇOS'!$E:$H,4,0)/(1-SUM($F$1))*VLOOKUP(CAPA!$B$12,'POLITICA DE PREÇO'!#REF!,2,0)*0.95,VLOOKUP(CONCATENATE(B13,$H$6),'BASE DE DADOS PREÇOS'!$E:$H,4,0)/(1-SUM($F$1))*VLOOKUP(CAPA!$B$12,'POLITICA DE PREÇO'!$B$4:$F$100,5,0))*CAPA!$B$14,"") -> 3725.2907 | I13: =IFERROR(IF('BASE DE DADOS PREÇOS'!$M$71="com",VLOOKUP(CONCATENATE(B13,$I$6),'BASE DE DADOS PREÇOS'!$E:$H,4,0)/(1-SUM($F$1))*VLOOKUP(CAPA!$B$12,'POLITICA DE PREÇO'!#REF!,2,0)*0.95,VLOOKUP(CONCATENATE(B13,$I$6),'BASE DE DADOS PREÇOS'!$E:$H,4,0)/(1-SUM($F$1))*VLOOKUP(CAPA!$B$12,'POLITICA DE PREÇO'!$B$4:$F$100,5,0))*CAPA!$B$14,"") -> 7432.0488 | J13: =I13*0.9 -> 6688.8439 | K13: =H13*1.05 -> 3911.5552
B14: Taijin Aparador - 1.8x0.5x0.79 - Acabamentos Customizados | C14: 1.8 | D14: 0.5 | E14: 0.79 | G14: =IFERROR(IF('BASE DE DADOS PREÇOS'!$M$71="com",VLOOKUP(CONCATENATE(B14,$G$6),'BASE DE DADOS PREÇOS'!$E:$H,4,0)/(1-SUM($F$1))*VLOOKUP(CAPA!$B$12,'POLITICA DE PREÇO'!#REF!,2,0)*0.95,VLOOKUP(CONCATENATE(B14,$G$6),'BASE DE DADOS PREÇOS'!$E:$H,4,0)/(1-SUM($F$1))*VLOOKUP(CAPA!$B$12,'POLITICA DE PREÇO'!$B$4:$F$100,5,0))*CAPA!$B$14,"") -> 4990.8096 | H14: =IFERROR(IF('BASE DE DADOS PREÇOS'!$M$71="com",VLOOKUP(CONCATENATE(B14,$H$6),'BASE DE DADOS PREÇOS'!$E:$H,4,0)/(1-SUM($F$1))*VLOOKUP(CAPA!$B$12,'POLITICA DE PREÇO'!#REF!,2,0)*0.95,VLOOKUP(CONCATENATE(B14,$H$6),'BASE DE DADOS PREÇOS'!$E:$H,4,0)/(1-SUM($F$1))*VLOOKUP(CAPA!$B$12,'POLITICA DE PREÇO'!$B$4:$F$100,5,0))*CAPA!$B$14,"") -> 4007.527 | I14: =IFERROR(IF('BASE DE DADOS PREÇOS'!$M$71="com",VLOOKUP(CONCATENATE(B14,$I$6),'BASE DE DADOS PREÇOS'!$E:$H,4,0)/(1-SUM($F$1))*VLOOKUP(CAPA!$B$12,'POLITICA DE PREÇO'!#REF!,2,0)*0.95,VLOOKUP(CONCATENATE(B14,$I$6),'BASE DE DADOS PREÇOS'!$E:$H,4,0)/(1-SUM($F$1))*VLOOKUP(CAPA!$B$12,'POLITICA DE PREÇO'!$B$4:$F$100,5,0))*CAPA!$B$14,"") -> 8176.8255 | J14: =I14*0.9 -> 7359.1429 | K14: =H14*1.05 -> 4207.9034
B15: Taijin Aparador - 2x0.5x0.79 - Acabamentos Customizados | C15: 2 | D15: 0.5 | E15: 0.79 | G15: =IFERROR(IF('BASE DE DADOS PREÇOS'!$M$71="com",VLOOKUP(CONCATENATE(B15,$G$6),'BASE DE DADOS PREÇOS'!$E:$H,4,0)/(1-SUM($F$1))*VLOOKUP(CAPA!$B$12,'POLITICA DE PREÇO'!#REF!,2,0)*0.95,VLOOKUP(CONCATENATE(B15,$G$6),'BASE DE DADOS PREÇOS'!$E:$H,4,0)/(1-SUM($F$1))*VLOOKUP(CAPA!$B$12,'POLITICA DE PREÇO'!$B$4:$F$100,5,0))*CAPA!$B$14,"") -> 5394.4517 | H15: =IFERROR(IF('BASE DE DADOS PREÇOS'!$M$71="com",VLOOKUP(CONCATENATE(B15,$H$6),'BASE DE DADOS PREÇOS'!$E:$H,4,0)/(1-SUM($F$1))*VLOOKUP(CAPA!$B$12,'POLITICA DE PREÇO'!#REF!,2,0)*0.95,VLOOKUP(CONCATENATE(B15,$H$6),'BASE DE DADOS PREÇOS'!$E:$H,4,0)/(1-SUM($F$1))*VLOOKUP(CAPA!$B$12,'POLITICA DE PREÇO'!$B$4:$F$100,5,0))*CAPA!$B$14,"") -> 4292.1814 | I15: =IFERROR(IF('BASE DE DADOS PREÇOS'!$M$71="com",VLOOKUP(CONCATENATE(B15,$I$6),'BASE DE DADOS PREÇOS'!$E:$H,4,0)/(1-SUM($F$1))*VLOOKUP(CAPA!$B$12,'POLITICA DE PREÇO'!#REF!,2,0)*0.95,VLOOKUP(CONCATENATE(B15,$I$6),'BASE DE DADOS PREÇOS'!$E:$H,4,0)/(1-SUM($F$1))*VLOOKUP(CAPA!$B$12,'POLITICA DE PREÇO'!$B$4:$F$100,5,0))*CAPA!$B$14,"") -> 8924.0044 | J15: =I15*0.9 -> 8031.6039 | K15: =H15*1.05 -> 4506.7904
B16: Taijin Aparador Com Gaveta - 1.6x0.5x0.79 - Acabamentos Customizados | C16: 1.6 | D16: 0.5 | E16: 0.79 | G16: =IFERROR(IF('BASE DE DADOS PREÇOS'!$M$71="com",VLOOKUP(CONCATENATE(B16,$G$6),'BASE DE DADOS PREÇOS'!$E:$H,4,0)/(1-SUM($F$1))*VLOOKUP(CAPA!$B$12,'POLITICA DE PREÇO'!#REF!,2,0)*0.95,VLOOKUP(CONCATENATE(B16,$G$6),'BASE DE DADOS PREÇOS'!$E:$H,4,0)/(1-SUM($F$1))*VLOOKUP(CAPA!$B$12,'POLITICA DE PREÇO'!$B$4:$F$100,5,0))*CAPA!$B$14,"") -> 4895.9677 | H16: =IFERROR(IF('BASE DE DADOS PREÇOS'!$M$71="com",VLOOKUP(CONCATENATE(B16,$H$6),'BASE DE DADOS PREÇOS'!$E:$H,4,0)/(1-SUM($F$1))*VLOOKUP(CAPA!$B$12,'POLITICA DE PREÇO'!#REF!,2,0)*0.95,VLOOKUP(CONCATENATE(B16,$H$6),'BASE DE DADOS PREÇOS'!$E:$H,4,0)/(1-SUM($F$1))*VLOOKUP(CAPA!$B$12,'POLITICA DE PREÇO'!$B$4:$F$100,5,0))*CAPA!$B$14,"") -> 4031.7938 | I16: =IFERROR(IF('BASE DE DADOS PREÇOS'!$M$71="com",VLOOKUP(CONCATENATE(B16,$I$6),'BASE DE DADOS PREÇOS'!$E:$H,4,0)/(1-SUM($F$1))*VLOOKUP(CAPA!$B$12,'POLITICA DE PREÇO'!#REF!,2,0)*0.95,VLOOKUP(CONCATENATE(B16,$I$6),'BASE DE DADOS PREÇOS'!$E:$H,4,0)/(1-SUM($F$1))*VLOOKUP(CAPA!$B$12,'POLITICA DE PREÇO'!$B$4:$F$100,5,0))*CAPA!$B$14,"") -> 7720.5223 | J16: =I16*0.9 -> 6948.4701 | K16: =H16*1.05 -> 4233.3835
B17: Taijin Aparador Com Gaveta - 1.8x0.5x0.79 - Acabamentos Customizados | C17: 1.8 | D17: 0.5 | E17: 0.79 | G17: =IFERROR(IF('BASE DE DADOS PREÇOS'!$M$71="com",VLOOKUP(CONCATENATE(B17,$G$6),'BASE DE DADOS PREÇOS'!$E:$H,4,0)/(1-SUM($F$1))*VLOOKUP(CAPA!$B$12,'POLITICA DE PREÇO'!#REF!,2,0)*0.95,VLOOKUP(CONCATENATE(B17,$G$6),'BASE DE DADOS PREÇOS'!$E:$H,4,0)/(1-SUM($F$1))*VLOOKUP(CAPA!$B$12,'POLITICA DE PREÇO'!$B$4:$F$100,5,0))*CAPA!$B$14,"") -> 5297.3127 | H17: =IFERROR(IF('BASE DE DADOS PREÇOS'!$M$71="com",VLOOKUP(CONCATENATE(B17,$H$6),'BASE DE DADOS PREÇOS'!$E:$H,4,0)/(1-SUM($F$1))*VLOOKUP(CAPA!$B$12,'POLITICA DE PREÇO'!#REF!,2,0)*0.95,VLOOKUP(CONCATENATE(B17,$H$6),'BASE DE DADOS PREÇOS'!$E:$H,4,0)/(1-SUM($F$1))*VLOOKUP(CAPA!$B$12,'POLITICA DE PREÇO'!$B$4:$F$100,5,0))*CAPA!$B$14,"") -> 4314.0301 | I17: =IFERROR(IF('BASE DE DADOS PREÇOS'!$M$71="com",VLOOKUP(CONCATENATE(B17,$I$6),'BASE DE DADOS PREÇOS'!$E:$H,4,0)/(1-SUM($F$1))*VLOOKUP(CAPA!$B$12,'POLITICA DE PREÇO'!#REF!,2,0)*0.95,VLOOKUP(CONCATENATE(B17,$I$6),'BASE DE DADOS PREÇOS'!$E:$H,4,0)/(1-SUM($F$1))*VLOOKUP(CAPA!$B$12,'POLITICA DE PREÇO'!$B$4:$F$100,5,0))*CAPA!$B$14,"") -> 8465.299 | J17: =I17*0.9 -> 7618.7691 | K17: =H17*1.05 -> 4529.7316
B18: Taijin Aparador Com Gaveta - 2x0.5x0.79 - Acabamentos Customizados | C18: 2 | D18: 0.5 | E18: 0.79 | G18: =IFERROR(IF('BASE DE DADOS PREÇOS'!$M$71="com",VLOOKUP(CONCATENATE(B18,$G$6),'BASE DE DADOS PREÇOS'!$E:$H,4,0)/(1-SUM($F$1))*VLOOKUP(CAPA!$B$12,'POLITICA DE PREÇO'!#REF!,2,0)*0.95,VLOOKUP(CONCATENATE(B18,$G$6),'BASE DE DADOS PREÇOS'!$E:$H,4,0)/(1-SUM($F$1))*VLOOKUP(CAPA!$B$12,'POLITICA DE PREÇO'!$B$4:$F$100,5,0))*CAPA!$B$14,"") -> 5700.9548 | H18: =IFERROR(IF('BASE DE DADOS PREÇOS'!$M$71="com",VLOOKUP(CONCATENATE(B18,$H$6),'BASE DE DADOS PREÇOS'!$E:$H,4,0)/(1-SUM($F$1))*VLOOKUP(CAPA!$B$12,'POLITICA DE PREÇO'!#REF!,2,0)*0.95,VLOOKUP(CONCATENATE(B18,$H$6),'BASE DE DADOS PREÇOS'!$E:$H,4,0)/(1-SUM($F$1))*VLOOKUP(CAPA!$B$12,'POLITICA DE PREÇO'!$B$4:$F$100,5,0))*CAPA!$B$14,"") -> 4598.6845 | I18: =IFERROR(IF('BASE DE DADOS PREÇOS'!$M$71="com",VLOOKUP(CONCATENATE(B18,$I$6),'BASE DE DADOS PREÇOS'!$E:$H,4,0)/(1-SUM($F$1))*VLOOKUP(CAPA!$B$12,'POLITICA DE PREÇO'!#REF!,2,0)*0.95,VLOOKUP(CONCATENATE(B18,$I$6),'BASE DE DADOS PREÇOS'!$E:$H,4,0)/(1-SUM($F$1))*VLOOKUP(CAPA!$B$12,'POLITICA DE PREÇO'!$B$4:$F$100,5,0))*CAPA!$B$14,"") -> 9212.4779 | J18: =I18*0.9 -> 8291.2301 | K18: =H18*1.05 -> 4828.6187

Sheet BUFFET
B2: TABELA DE PREÇO CENTURY | MADEIRA
C5: Dimensoes (metros)
A6: Imagem | B6: Nome | C6: C | D6: L | E6: A | G6: Tampo: Espelho Bronze, Fume, Prata, Vidro Fosco ou Clear Corpo: Laca ou Lamina | H6: Tampo: Laca ou Lamina com ou sem Vidro Normal Pintado Corpo: Laca ou Lamina | I6: Tampo: Mármore ou Porcelana Especial Corpo: Laca ou Lamina | J6: Tampo: Mármore Normal Corpo: Laca ou Lamina | K6: Tampo ou Base em Recoro
B7: Mantova Buffet - 2x0.5x76 - Acabamentos Customizados | C7: 2 | D7: 0.5 | E7: 0.76 | G7: =IFERROR(IF('BASE DE DADOS PREÇOS'!$M$71="com",VLOOKUP(CONCATENATE(B7,$G$6),'BASE DE DADOS PREÇOS'!$E:$H,4,0)/(1-SUM($G$1))*VLOOKUP(CAPA!$B$12,'POLITICA DE PREÇO'!#REF!,2,0)*0.95,VLOOKUP(CONCATENATE(B7,$G$6),'BASE DE DADOS PREÇOS'!$E:$H,4,0)/(1-SUM($G$1))*VLOOKUP(CAPA!$B$12,'POLITICA DE PREÇO'!$B$4:$F$100,5,0))*CAPA!$B$14,"") -> 9702.4251 | H7: =IFERROR(IF('BASE DE DADOS PREÇOS'!$M$71="com",VLOOKUP(CONCATENATE(B7,$H$6),'BASE DE DADOS PREÇOS'!$E:$H,4,0)/(1-SUM($G$1))*VLOOKUP(CAPA!$B$12,'POLITICA DE PREÇO'!#REF!,2,0)*0.95,VLOOKUP(CONCATENATE(B7,$H$6),'BASE DE DADOS PREÇOS'!$E:$H,4,0)/(1-SUM($G$1))*VLOOKUP(CAPA!$B$12,'POLITICA DE PREÇO'!$B$4:$F$100,5,0))*CAPA!$B$14,"") -> 8144.2059 | I7: =IFERROR(IF('BASE DE DADOS PREÇOS'!$M$71="com",VLOOKUP(CONCATENATE(B7,$I$6),'BASE DE DADOS PREÇOS'!$E:$H,4,0)/(1-SUM($G$1))*VLOOKUP(CAPA!$B$12,'POLITICA DE PREÇO'!#REF!,2,0)*0.95,VLOOKUP(CONCATENATE(B7,$I$6),'BASE DE DADOS PREÇOS'!$E:$H,4,0)/(1-SUM($G$1))*VLOOKUP(CAPA!$B$12,'POLITICA DE PREÇO'!$B$4:$F$100,5,0))*CAPA!$B$14,"") -> 13200.611 | J7: =I7*0.9 -> 11880.55
B8: Mantova Buffet - 2.2x0.5x76 - Acabamentos Customizados | C8: 2.2 | D8: 0.5 | E8: 0.76 | G8: =IFERROR(IF('BASE DE DADOS PREÇOS'!$M$71="com",VLOOKUP(CONCATENATE(B8,$G$6),'BASE DE DADOS PREÇOS'!$E:$H,4,0)/(1-SUM($G$1))*VLOOKUP(CAPA!$B$12,'POLITICA DE PREÇO'!#REF!,2,0)*0.95,VLOOKUP(CONCATENATE(B8,$G$6),'BASE DE DADOS PREÇOS'!$E:$H,4,0)/(1-SUM($G$1))*VLOOKUP(CAPA!$B$12,'POLITICA DE PREÇO'!$B$4:$F$100,5,0))*CAPA!$B$14,"") -> 9974.3609 | H8: =IFERROR(IF('BASE DE DADOS PREÇOS'!$M$71="com",VLOOKUP(CONCATENATE(B8,$H$6),'BASE DE DADOS PREÇOS'!$E:$H,4,0)/(1-SUM($G$1))*VLOOKUP(CAPA!$B$12,'POLITICA DE PREÇO'!#REF!,2,0)*0.95,VLOOKUP(CONCATENATE(B8,$H$6),'BASE DE DADOS PREÇOS'!$E:$H,4,0)/(1-SUM($G$1))*VLOOKUP(CAPA!$B$12,'POLITICA DE PREÇO'!$B$4:$F$100,5,0))*CAPA!$B$14,"") -> 8429.4784 | I8: =IFERROR(IF('BASE DE DADOS PREÇOS'!$M$71="com",VLOOKUP(CONCATENATE(B8,$I$6),'BASE DE DADOS PREÇOS'!$E:$H,4,0)/(1-SUM($G$1))*VLOOKUP(CAPA!$B$12,'POLITICA DE PREÇO'!#REF!,2,0)*0.95,VLOOKUP(CONCATENATE(B8,$I$6),'BASE DE DADOS PREÇOS'!$E:$H,4,0)/(1-SUM($G$1))*VLOOKUP(CAPA!$B$12,'POLITICA DE PREÇO'!$B$4:$F$100,5,0))*CAPA!$B$14,"") -> 13908.141 | J8: =I8*0.9 -> 12517.327
B9: Mantova Buffet - 2.4x0.5x76 - Acabamentos Customizados | C9: 2.4 | D9: 0.5 | E9: 0.76 | G9: =IFERROR(IF('BASE DE DADOS PREÇOS'!$M$71="com",VLOOKUP(CONCATENATE(B9,$G$6),'BASE DE DADOS PREÇOS'!$E:$H,4,0)/(1-SUM($G$1))*VLOOKUP(CAPA!$B$12,'POLITICA DE PREÇO'!#REF!,2,0)*0.95,VLOOKUP(CONCATENATE(B9,$G$6),'BASE DE DADOS PREÇOS'!$E:$H,4,0)/(1-SUM($G$1))*VLOOKUP(CAPA!$B$12,'POLITICA DE PREÇO'!$B$4:$F$100,5,0))*CAPA!$B$14,"") -> 10338.43 | H9: =IFERROR(IF('BASE DE DADOS PREÇOS'!$M$71="com",VLOOKUP(CONCATENATE(B9,$H$6),'BASE DE DADOS PREÇOS'!$E:$H,4,0)/(1-SUM($G$1))*VLOOKUP(CAPA!$B$12,'POLITICA DE PREÇO'!#REF!,2,0)*0.95,VLOOKUP(CONCATENATE(B9,$H$6),'BASE DE DADOS PREÇOS'!$E:$H,4,0)/(1-SUM($G$1))*VLOOKUP(CAPA!$B$12,'POLITICA DE PREÇO'!$B$4:$F$100,5,0))*CAPA!$B$14,"") -> 9177.0523 | I9: =IFERROR(IF('BASE DE DADOS PREÇOS'!$M$71="com",VLOOKUP(CONCATENATE(B9,$I$6),'BASE DE DADOS PREÇOS'!$E:$H,4,0)/(1-SUM($G$1))*VLOOKUP(CAPA!$B$12,'POLITICA DE PREÇO'!#REF!,2,0)*0.95,VLOOKUP(CONCATENATE(B9,$I$6),'BASE DE DADOS PREÇOS'!$E:$H,4,0)/(1-SUM($G$1))*VLOOKUP(CAPA!$B$12,'POLITICA DE PREÇO'!$B$4:$F$100,5,0))*CAPA!$B$14,"") -> 14724.157 | J9: =I9*0.9 -> 13251.741
B10: Modena Buffet - 2x0.5x76 - Acabamentos Customizados | C10: 2 | D10: 0.5 | E10: 0.76 | G10: =IFERROR(IF('BASE DE DADOS PREÇOS'!$M$71="com",VLOOKUP(CONCATENATE(B10,$G$6),'BASE DE DADOS PREÇOS'!$E:$H,4,0)/(1-SUM($G$1))*VLOOKUP(CAPA!$B$12,'POLITICA DE PREÇO'!#REF!,2,0)*0.95,VLOOKUP(CONCATENATE(B10,$G$6),'BASE DE DADOS PREÇOS'!$E:$H,4,0)/(1-SUM($G$1))*VLOOKUP(CAPA!$B$12,'POLITICA DE PREÇO'!$B$4:$F$100,5,0))*CAPA!$B$14,"") -> 9713.2448 | H10: =IFERROR(IF('BASE DE DADOS PREÇOS'!$M$71="com",VLOOKUP(CONCATENATE(B10,$H$6),'BASE DE DADOS PREÇOS'!$E:$H,4,0)/(1-SUM($G$1))*VLOOKUP(CAPA!$B$12,'POLITICA DE PREÇO'!#REF!,2,0)*0.95,VLOOKUP(CONCATENATE(B10,$H$6),'BASE DE DADOS PREÇOS'!$E:$H,4,0)/(1-SUM($G$1))*VLOOKUP(CAPA!$B$12,'POLITICA DE PREÇO'!$B$4:$F$100,5,0))*CAPA!$B$14,"") -> 8160.8946 | I10: =IFERROR(IF('BASE DE DADOS PREÇOS'!$M$71="com",VLOOKUP(CONCATENATE(B10,$I$6),'BASE DE DADOS PREÇOS'!$E:$H,4,0)/(1-SUM($G$1))*VLOOKUP(CAPA!$B$12,'POLITICA DE PREÇO'!#REF!,2,0)*0.95,VLOOKUP(CONCATENATE(B10,$I$6),'BASE DE DADOS PREÇOS'!$E:$H,4,0)/(1-SUM($G$1))*VLOOKUP(CAPA!$B$12,'POLITICA DE PREÇO'!$B$4:$F$100,5,0))*CAPA!$B$14,"") -> 13487.504 | J10: =I10*0.9 -> 12138.754
B11: Modena Buffet - 2.2x0.5x76 - Acabamentos Customizados | C11: 2.2 | D11: 0.5 | E11: 0.76 | G11: =IFERROR(IF('BASE DE DADOS PREÇOS'!$M$71="com",VLOOKUP(CONCATENATE(B11,$G$6),'BASE DE DADOS PREÇOS'!$E:$H,4,0)/(1-SUM($G$1))*VLOOKUP(CAPA!$B$12,'POLITICA DE PREÇO'!#REF!,2,0)*0.95,VLOOKUP(CONCATENATE(B11,$G$6),'BASE DE DADOS PREÇOS'!$E:$H,4,0)/(1-SUM($G$1))*VLOOKUP(CAPA!$B$12,'POLITICA DE PREÇO'!$B$4:$F$100,5,0))*CAPA!$B$14,"") -> 9851.9858 | H11: =IFERROR(IF('BASE DE DADOS PREÇOS'!$M$71="com",VLOOKUP(CONCATENATE(B11,$H$6),'BASE DE DADOS PREÇOS'!$E:$H,4,0)/(1-SUM($G$1))*VLOOKUP(CAPA!$B$12,'POLITICA DE PREÇO'!#REF!,2,0)*0.95,VLOOKUP(CONCATENATE(B11,$H$6),'BASE DE DADOS PREÇOS'!$E:$H,4,0)/(1-SUM($G$1))*VLOOKUP(CAPA!$B$12,'POLITICA DE PREÇO'!$B$4:$F$100,5,0))*CAPA!$B$14,"") -> 8517.7873 | I11: =IFERROR(IF('BASE DE DADOS PREÇOS'!$M$71="com",VLOOKUP(CONCATENATE(B11,$I$6),'BASE DE DADOS PREÇOS'!$E:$H,4,0)/(1-SUM($G$1))*VLOOKUP(CAPA!$B$12,'POLITICA DE PREÇO'!#REF!,2,0)*0.95,VLOOKUP(CONCATENATE(B11,$I$6),'BASE DE DADOS PREÇOS'!$E:$H,4,0)/(1-SUM($G$1))*VLOOKUP(CAPA!$B$12,'POLITICA DE PREÇO'!$B$4:$F$100,5,0))*CAPA!$B$14,"") -> 14229.144 | J11: =I11*0.9 -> 12806.229
B12: Modena Buffet - 2.4x0.5x76 - Acabamentos Customizados | C12: 2.4 | D12: 0.5 | E12: 0.76 | G12: =IFERROR(IF('BASE DE DADOS PREÇOS'!$M$71="com",VLOOKUP(CONCATENATE(B12,$G$6),'BASE DE DADOS PREÇOS'!$E:$H,4,0)/(1-SUM($G$1))*VLOOKUP(CAPA!$B$12,'POLITICA DE PREÇO'!#REF!,2,0)*0.95,VLOOKUP(CONCATENATE(B12,$G$6),'BASE DE DADOS PREÇOS'!$E:$H,4,0)/(1-SUM($G$1))*VLOOKUP(CAPA!$B$12,'POLITICA DE PREÇO'!$B$4:$F$100,5,0))*CAPA!$B$14,"") -> 10243.881 | H12: =IFERROR(IF('BASE DE DADOS PREÇOS'!$M$71="com",VLOOKUP(CONCATENATE(B12,$H$6),'BASE DE DADOS PREÇOS'!$E:$H,4,0)/(1-SUM($G$1))*VLOOKUP(CAPA!$B$12,'POLITICA DE PREÇO'!#REF!,2,0)*0.95,VLOOKUP(CONCATENATE(B12,$H$6),'BASE DE DADOS PREÇOS'!$E:$H,4,0)/(1-SUM($G$1))*VLOOKUP(CAPA!$B$12,'POLITICA DE PREÇO'!$B$4:$F$100,5,0))*CAPA!$B$14,"") -> 9368.4558 | I12: =IFERROR(IF('BASE DE DADOS PREÇOS'!$M$71="com",VLOOKUP(CONCATENATE(B12,$I$6),'BASE DE DADOS PREÇOS'!$E:$H,4,0)/(1-SUM($G$1))*VLOOKUP(CAPA!$B$12,'POLITICA DE PREÇO'!#REF!,2,0)*0.95,VLOOKUP(CONCATENATE(B12,$I$6),'BASE DE DADOS PREÇOS'!$E:$H,4,0)/(1-SUM($G$1))*VLOOKUP(CAPA!$B$12,'POLITICA DE PREÇO'!$B$4:$F$100,5,0))*CAPA!$B$14,"") -> 15189.577 | J12: =I12*0.9 -> 13670.619
B13: Modena Bar - 1.3x0.5x76 - Acabamentos Customizados | C13: 1.3 | D13: 0.5 | E13: 0.76 | G13: =IFERROR(IF('BASE DE DADOS PREÇOS'!$M$71="com",VLOOKUP(CONCATENATE(B13,$G$6),'BASE DE DADOS PREÇOS'!$E:$H,4,0)/(1-SUM($G$1))*VLOOKUP(CAPA!$B$12,'POLITICA DE PREÇO'!#REF!,2,0)*0.95,VLOOKUP(CONCATENATE(B13,$G$6),'BASE DE DADOS PREÇOS'!$E:$H,4,0)/(1-SUM($G$1))*VLOOKUP(CAPA!$B$12,'POLITICA DE PREÇO'!$B$4:$F$100,5,0))*CAPA!$B$14,"") -> 6426.2923 | H13: =IFERROR(IF('BASE DE DADOS PREÇOS'!$M$71="com",VLOOKUP(CONCATENATE(B13,$H$6),'BASE DE DADOS PREÇOS'!$E:$H,4,0)/(1-SUM($G$1))*VLOOKUP(CAPA!$B$12,'POLITICA DE PREÇO'!#REF!,2,0)*0.95,VLOOKUP(CONCATENATE(B13,$H$6),'BASE DE DADOS PREÇOS'!$E:$H,4,0)/(1-SUM($G$1))*VLOOKUP(CAPA!$B$12,'POLITICA DE PREÇO'!$B$4:$F$100,5,0))*CAPA!$B$14,"") -> 5860.1048 | I13: =IFERROR(IF('BASE DE DADOS PREÇOS'!$M$71="com",VLOOKUP(CONCATENATE(B13,$I$6),'BASE DE DADOS PREÇOS'!$E:$H,4,0)/(1-SUM($G$1))*VLOOKUP(CAPA!$B$12,'POLITICA DE PREÇO'!#REF!,2,0)*0.95,VLOOKUP(CONCATENATE(B13,$I$6),'BASE DE DADOS PREÇOS'!$E:$H,4,0)/(1-SUM($G$1))*VLOOKUP(CAPA!$B$12,'POLITICA DE PREÇO'!$B$4:$F$100,5,0))*CAPA!$B$14,"") -> 8533.0382 | J13: =I13*0.9 -> 7679.7344

Sheet BASE DE DADOS PREÇOS
C1: Imagem | D1: Item/Module | F1: Nome | G1: Acabamento | H1: Preco Unitario (Real) | S1: PREÇO PRÉ AJUSTES | T1: PREÇO SEM OVER | U1: REAJUSTE 7% | V1: OVER 16,63 | W1: OVER 5,26 PARA NEGOCIAÇÕES
E2: =F2&G2 -> BRIDGE BUFFET 2.0X0.55X0.8 - Acabamentos CustomizadosTampo: Espelho Bronze, Fume, Prata, Vidro Fosco ou Clear Corpo: Laca ou Lamina | F2: BRIDGE BUFFET 2.0X0.55X0.8 - Acabamentos Customizados | G2: Tampo: Espelho Bronze, Fume, Prata, Vidro Fosco ou Clear Corpo: Laca ou Lamina | H2: 10201.078 | N2: 8594.8055 | P2: #N/A | S2: 8134.2732 | T2: =IF(S2,S2*(1-0.05)) -> 7727.5595 | U2: =IF(T2,T2/(1-0.07)) -> 8309.2038 | V2: =U2*1.1663 -> 9691.0244 | W2: =V2*1.05263157894 -> 10201.078
E3: =F3&G3 -> BRIDGE BUFFET 2.0X0.55X0.8 - Acabamentos CustomizadosTampo: Laca ou Lamina com ou sem Vidro Normal Pintado Corpo: Laca ou Lamina | F3: BRIDGE BUFFET 2.0X0.55X0.8 - Acabamentos Customizados | G3: Tampo: Laca ou Lamina com ou sem Vidro Normal Pintado Corpo: Laca ou Lamina | H3: 8543.1718 | N3: 9912.0891 | P3: #N/A | S3: 6812.2693 | T3: =IF(S3,S3*(1-0.05)) -> 6471.6559 | U3: =IF(T3,T3/(1-0.07)) -> 6958.7698 | V3: =U3*1.1663 -> 8116.0132 | W3: =V3*1.05263157894 -> 8543.1718
E4: =F4&G4 -> BRIDGE BUFFET 2.0X0.55X0.8 - Acabamentos CustomizadosTampo: Mármore ou Porcelana Especial Corpo: Laca ou Lamina | F4: BRIDGE BUFFET 2.0X0.55X0.8 - Acabamentos Customizados | G4: Tampo: Mármore ou Porcelana Especial Corpo: Laca ou Lamina | H4: 14649.577 | N4: 15023.58 | P4: #N/A | S4: 11681.477 | T4: =IF(S4,S4*(1-0.05)) -> 11097.403 | U4: =IF(T4,T4/(1-0.07)) -> 11932.692 | V4: =U4*1.1663 -> 13917.099 | W4: =V4*1.05263157894 -> 14649.577
E5: =F5&G5 -> BRIDGE BUFFET 2.2X0.55X0.8 - Acabamentos CustomizadosTampo: Espelho Bronze, Fume, Prata, Vidro Fosco ou Clear Corpo: Laca ou Lamina | F5: BRIDGE BUFFET 2.2X0.55X0.8 - Acabamentos Customizados | G5: Tampo: Espelho Bronze, Fume, Prata, Vidro Fosco ou Clear Corpo: Laca ou Lamina | H5: 10460.36 | S5: 8341.023 | T5: =IF(S5,S5*(1-0.05)) -> 7923.9719 | U5: =IF(T5,T5/(1-0.07)) -> 8520.3998 | V5: =U5*1.1663 -> 9937.3423 | W5: =V5*1.05263157894 -> 10460.36
E6: =F6&G6 -> BRIDGE BUFFET 2.2X0.55X0.8 - Acabamentos CustomizadosTampo: Laca ou Lamina com ou sem Vidro Normal Pintado Corpo: Laca ou Lamina | F6: BRIDGE BUFFET 2.2X0.55X0.8 - Acabamentos Customizados | G6: Tampo: Laca ou Lamina com ou sem Vidro Normal Pintado Corpo: Laca ou Lamina | H6: 9070.2133 | S6: 7232.5288 | T6: =IF(S6,S6*(1-0.05)) -> 6870.9024 | U6: =IF(T6,T6/(1-0.07)) -> 7388.0671 | V6: =U6*1.1663 -> 8616.7026 | W6: =V6*1.05263157894 -> 9070.2133
E7: =F7&G7 -> BRIDGE BUFFET 2.2X0.55X0.8 - Acabamentos CustomizadosTampo: Mármore ou Porcelana Especial Corpo: Laca ou Lamina | F7: BRIDGE BUFFET 2.2X0.55X0.8 - Acabamentos Customizados | G7: Tampo: Mármore ou Porcelana Especial Corpo: Laca ou Lamina | H7: 15133.922 | S7: 12067.69 | T7: =IF(S7,S7*(1-0.05)) -> 11464.306 | U7: =IF(T7,T7/(1-0.07)) -> 12327.21 | V7: =U7*1.1663 -> 14377.226 | W7: =V7*1.05263157894 -> 15133.922
E8: =F8&G8 -> BRIDGE BUFFET 2.4X0.55X0.8 - Acabamentos CustomizadosTampo: Espelho Bronze, Fume, Prata, Vidro Fosco ou Clear Corpo: Laca ou Lamina | F8: BRIDGE BUFFET 2.4X0.55X0.8 - Acabamentos Customizados | G8: Tampo: Espelho Bronze, Fume, Prata, Vidro Fosco ou Clear Corpo: Laca ou Lamina | H8: 11125.394 | S8: 8871.3164 | T8: =IF(S8,S8*(1-0.05)) -> 8427.7506 | U8: =IF(T8,T8/(1-0.07)) -> 9062.0974 | V8: =U8*1.1663 -> 10569.124 | W8: =V8*1.05263157894 -> 11125.394
E9: =F9&G9 -> BRIDGE BUFFET 2.4X0.55X0.8 - Acabamentos CustomizadosTampo: Laca ou Lamina com ou sem Vidro Normal Pintado Corpo: Laca ou Lamina | F9: BRIDGE BUFFET 2.4X0.55X0.8 - Acabamentos Customizados | G9: Tampo: Laca ou Lamina com ou sem Vidro Normal Pintado Corpo: Laca ou Lamina | H9: 9559.4811 | S9: 7622.6678 | T9: =IF(S9,S9*(1-0.05)) -> 7241.5344 | U9: =IF(T9,T9/(1-0.07)) -> 7786.5961 | V9: =U9*1.1663 -> 9081.5071 | W9: =V9*1.05263157894 -> 9559.4811
E10: =F10&G10 -> BRIDGE BUFFET 2.4X0.55X0.8 - Acabamentos CustomizadosTampo: Mármore ou Porcelana Especial Corpo: Laca ou Lamina | F10: BRIDGE BUFFET 2.4X0.55X0.8 - Acabamentos Customizados | G10: Tampo: Mármore ou Porcelana Especial Corpo: Laca ou Lamina | H10: 16249.816 | S10: 12957.497 | T10: =IF(S10,S10*(1-0.05)) -> 12309.622 | U10: =IF(T10,T10/(1-0.07)) -> 13236.153 | V10: =U10*1.1663 -> 15437.325 | W10: =V10*1.05263157894 -> 16249.816
E11: =F11&G11 -> AERIS BUFFET 2X0.45X0.77 - Acabamentos CustomizadosTampo: Laca ou Lamina com ou sem Vidro Normal Pintado Corpo: Laca ou Lamina | F11: AERIS BUFFET 2X0.45X0.77 - Acabamentos Customizados | G11: Tampo: Laca ou Lamina com ou sem Vidro Normal Pintado Corpo: Laca ou Lamina | H11: 8263.577 | I11: =H11*1.12 -> 9255.2063 | S11: 6589.3223 | T11: =IF(S11,S11*(1-0.05)) -> 6259.8562 | U11: =IF(T11,T11/(1-0.07)) -> 6731.0282 | V11: =U11*1.1663 -> 7850.3982 | W11: =V11*1.05263157894 -> 8263.577
E12: =F12&G12 -> AERIS BUFFET 2X0.45X0.77 - Acabamentos CustomizadosTampo: Espelho Bronze, Fume, Prata, Vidro Fosco ou Clear Corpo: Laca ou Lamina | F12: AERIS BUFFET 2X0.45X0.77 - Acabamentos Customizados | G12: Tampo: Espelho Bronze, Fume, Prata, Vidro Fosco ou Clear Corpo: Laca ou Lamina | H12: 9438.215 | I12: =H12*1.12 -> 10570.801 | S12: 7525.971 | T12: =IF(S12,S12*(1-0.05)) -> 7149.6724 | U12: =IF(T12,T12/(1-0.07)) -> 7687.8198 | V12: =U12*1.1663 -> 8966.3043 | W12: =V12*1.05263157894 -> 9438.215
E13: =F13&G13 -> AERIS BUFFET 2X0.45X0.77 - Acabamentos CustomizadosTampo: Mármore ou Porcelana Especial Corpo: Laca ou Lamina | F13: AERIS BUFFET 2X0.45X0.77 - Acabamentos Customizados | G13: Tampo: Mármore ou Porcelana Especial Corpo: Laca ou Lamina | H13: 15041.713 | I13: =H13*1.07 -> 16094.632 | S13: 11994.163 | T13: =IF(S13,S13*(1-0.05)) -> 11394.455 | U13: =IF(T13,T13/(1-0.07)) -> 12252.102 | V13: =U13*1.1663 -> 14289.627 | W13: =V13*1.05263157894 -> 15041.713
E14: =F14&G14 -> AERIS BUFFET 2.2X0.45X0.77 - Acabamentos CustomizadosTampo: Laca ou Lamina com ou sem Vidro Normal Pintado Corpo: Laca ou Lamina | F14: AERIS BUFFET 2.2X0.45X0.77 - Acabamentos Customizados | G14: Tampo: Laca ou Lamina com ou sem Vidro Normal Pintado Corpo: Laca ou Lamina | H14: 8773.3699 | I14: =H14*1.12 -> 9826.1743 | S14: 6995.8279 | T14: =IF(S14,S14*(1-0.05)) -> 6646.0365 | U14: =IF(T14,T14/(1-0.07)) -> 7146.2758 | V14: =U14*1.1663 -> 8334.7014 | W14: =V14*1.05263157894 -> 8773.3699
E15: =F15&G15 -> AERIS BUFFET 2.2X0.45X0.77 - Acabamentos CustomizadosTampo: Espelho Bronze, Fume, Prata, Vidro Fosco ou Clear Corpo: Laca ou Lamina | F15: AERIS BUFFET 2.2X0.45X0.77 - Acabamentos Customizados | G15: Tampo: Espelho Bronze, Fume, Prata, Vidro Fosco ou Clear Corpo: Laca ou Lamina | H15: 10118.021 | I15: =H15*1.12 -> 11332.184 | S15: 8068.0441 | T15: =IF(S15,S15*(1-0.05)) -> 7664.6419 | U15: =IF(T15,T15/(1-0.07)) -> 8241.5504 | V15: =U15*1.1663 -> 9612.1202 | W15: =V15*1.05263157894 -> 10118.021
E16: =F16&G16 -> AERIS BUFFET 2.2X0.45X0.77 - Acabamentos CustomizadosTampo: Mármore ou Porcelana Especial Corpo: Laca ou Lamina | F16: AERIS BUFFET 2.2X0.45X0.77 - Acabamentos Customizados | G16: Tampo: Mármore ou Porcelana Especial Corpo: Laca ou Lamina | H16: 16278.975 | I16: =H16*1.07 -> 17418.503 | S16: 12980.748 | T16: =IF(S16,S16*(1-0.05)) -> 12331.711 | U16: =IF(T16,T16/(1-0.07)) -> 13259.904 | V16: =U16*1.1663 -> 15465.026 | W16: =V16*1.05263157894 -> 16278.975
E17: =F17&G17 -> AERIS BUFFET 2.4X0.45X0.77 - Acabamentos CustomizadosTampo: Laca ou Lamina com ou sem Vidro Normal Pintado Corpo: Laca ou Lamina | F17: AERIS BUFFET 2.4X0.45X0.77 - Acabamentos Customizados | G17: Tampo: Laca ou Lamina com ou sem Vidro Normal Pintado Corpo: Laca ou Lamina | H17: 9246.6254 | I17: =H17*1.12 -> 10356.22 | S17: 7373.1987 | T17: =IF(S17,S17*(1-0.05)) -> 7004.5387 | U17: =IF(T17,T17/(1-0.07)) -> 7531.7621 | V17: =U17*1.1663 -> 8784.2941 | W17: =V17*1.05263157894 -> 9246.6254
E18: =F18&G18 -> AERIS BUFFET 2.4X0.45X0.77 - Acabamentos CustomizadosTampo: Espelho Bronze, Fume, Prata, Vidro Fosco ou Clear Corpo: Laca ou Lamina | F18: AERIS BUFFET 2.4X0.45X0.77 - Acabamentos Customizados | G18: Tampo: Espelho Bronze, Fume, Prata, Vidro Fosco ou Clear Corpo: Laca ou Lamina | H18: 10761.29 | I18: =H18*1.12 -> 12052.645 | S18: 8580.9825 | T18: =IF(S18,S18*(1-0.05)) -> 8151.9333 | U18: =IF(T18,T18/(1-0.07)) -> 8765.5197 | V18: =U18*1.1663 -> 10223.226 | W18: =V18*1.05263157894 -> 10761.29
E19: =F19&G19 -> AERIS BUFFET 2.4X0.45X0.77 - Acabamentos CustomizadosTampo: Mármore ou Porcelana Especial Corpo: Laca ou Lamina | F19: AERIS BUFFET 2.4X0.45X0.77 - Acabamentos Customizados | G19: Tampo: Mármore ou Porcelana Especial Corpo: Laca ou Lamina | H19: 17479.3 | I19: =H19*1.07 -> 18702.851 | S19: 13937.879 | T19: =IF(S19,S19*(1-0.05)) -> 13240.985 | U19: =IF(T19,T19/(1-0.07)) -> 14237.619 | V19: =U19*1.1663 -> 16605.335 | W19: =V19*1.05263157894 -> 17479.3
E20: =F20&G20 -> CHERI BUFFET 1.2X0.5X0.83 - Acabamentos CustomizadosTampo: Espelho Bronze, Fume, Prata, Vidro Fosco ou Clear Corpo: Laca ou Lamina | F20: CHERI BUFFET 1.2X0.5X0.83 - Acabamentos Customizados | G20: Tampo: Espelho Bronze, Fume, Prata, Vidro Fosco ou Clear Corpo: Laca ou Lamina | H20: 8711.6429 | N20: 6551.1532 | P20: 6066.6269 | S20: 6946.6071 | T20: =IF(S20,S20*(1-0.05)) -> 6599.2768 | U20: =IF(T20,T20/(1-0.07)) -> 7095.9965 | V20: =U20*1.1663 -> 8276.0608 | W20: =V20*1.05263157894 -> 8711.6429
E21: =F21&G21 -> CHERI BUFFET 1.2X0.5X0.83 - Acabamentos CustomizadosTampo: Laca ou Lamina com ou sem Vidro Normal Pintado Corpo: Laca ou Lamina | F21: CHERI BUFFET 1.2X0.5X0.83 - Acabamentos Customizados | G21: Tampo: Laca ou Lamina com ou sem Vidro Normal Pintado Corpo: Laca ou Lamina | H21: 7710.7246 | N21: 7633.9995 | P21: 5568.4802 | S21: 6148.4814 | T21: =IF(S21,S21*(1-0.05)) -> 5841.0573 | U21: =IF(T21,T21/(1-0.07)) -> 6280.7068 | V21: =U21*1.1663 -> 7325.1883 | W21: =V21*1.05263157894 -> 7710.7246
E22: =F22&G22 -> CHERI BUFFET 1.2X0.5X0.83 - Acabamentos CustomizadosTampo: Mármore ou Porcelana Especial Corpo: Laca ou Lamina | F22: CHERI BUFFET 1.2X0.5X0.83 - Acabamentos Customizados | G22: Tampo: Mármore ou Porcelana Especial Corpo: Laca ou Lamina | H22: 10874.987 | S22: 8671.6436 | T22: =IF(S22,S22*(1-0.05)) -> 8238.0614 | U22: =IF(T22,T22/(1-0.07)) -> 8858.1305 | V22: =U22*1.1663 -> 10331.238 | W22: =V22*1.05263157894 -> 10874.987
E23: =F23&G23 -> CHERI BUFFET 1.6X0.5X0.83 - Acabamentos CustomizadosTampo: Espelho Bronze, Fume, Prata, Vidro Fosco ou Clear Corpo: Laca ou Lamina | F23: CHERI BUFFET 1.6X0.5X0.83 - Acabamentos Customizados | G23: Tampo: Espelho Bronze, Fume, Prata, Vidro Fosco ou Clear Corpo: Laca ou Lamina | H23: 10270.179 | S23: 8189.3736 | T23: =IF(S23,S23*(1-0.05)) -> 7779.9049 | U23: =IF(T23,T23/(1-0.07)) -> 8365.4892 | V23: =U23*1.1663 -> 9756.67 | W23: =V23*1.05263157894 -> 10270.179
E24: =F24&G24 -> CHERI BUFFET 1.6X0.5X0.83 - Acabamentos CustomizadosTampo: Laca ou Lamina com ou sem Vidro Normal Pintado Corpo: Laca ou Lamina | F24: CHERI BUFFET 1.6X0.5X0.83 - Acabamentos Customizados | G24: Tampo: Laca ou Lamina com ou sem Vidro Normal Pintado Corpo: Laca ou Lamina | H24: 8486.0576 | S24: 6766.7269 | T24: =IF(S24,S24*(1-0.05)) -> 6428.3906 | U24: =IF(T24,T24/(1-0.07)) -> 6912.2479 | V24: =U24*1.1663 -> 8061.7547 | W24: =V24*1.05263157894 -> 8486.0576
E25: =F25&G25 -> CHERI BUFFET 1.6X0.5X0.83 - Acabamentos CustomizadosTampo: Mármore ou Porcelana Especial Corpo: Laca ou Lamina | F25: CHERI BUFFET 1.6X0.5X0.83 - Acabamentos Customizados | G25: Tampo: Mármore ou Porcelana Especial Corpo: Laca ou Lamina | H25: 13326.504 | N25: 8525.2327 | P25: #N/A | S25: 10626.467 | T25: =IF(S25,S25*(1-0.05)) -> 10095.144 | U25: =IF(T25,T25/(1-0.07)) -> 10854.993 | V25: =U25*1.1663 -> 12660.179 | W25: =V25*1.05263157894 -> 13326.504
E26: =F26&G26 -> CHERI BUFFET 1.8X0.5X0.83 - Acabamentos CustomizadosTampo: Espelho Bronze, Fume, Prata, Vidro Fosco ou Clear Corpo: Laca ou Lamina | F26: CHERI BUFFET 1.8X0.5X0.83 - Acabamentos Customizados | G26: Tampo: Espelho Bronze, Fume, Prata, Vidro Fosco ou Clear Corpo: Laca ou Lamina | H26: 10810.715 | N26: 7137.2082 | P26: #N/A | S26: 8620.3933 | T26: =IF(S26,S26*(1-0.05)) -> 8189.3736 | U26: =IF(T26,T26/(1-0.07)) -> 8805.7781 | V26: =U26*1.1663 -> 10270.179 | W26: =V26*1.05263157894 -> 10810.715
E27: =F27&G27 -> CHERI BUFFET 1.8X0.5X0.83 - Acabamentos CustomizadosTampo: Laca ou Lamina com ou sem Vidro Normal Pintado Corpo: Laca ou Lamina | F27: CHERI BUFFET 1.8X0.5X0.83 - Acabamentos Customizados | G27: Tampo: Laca ou Lamina com ou sem Vidro Normal Pintado Corpo: Laca ou Lamina | H27: 8932.6922 | N27: 8414.0737 | P27: #N/A | S27: 7122.8704 | T27: =IF(S27,S27*(1-0.05)) -> 6766.7269 | U27: =IF(T27,T27/(1-0.07)) -> 7276.0504 | V27: =U27*1.1663 -> 8486.0576 | W27: =V27*1.05263157894 -> 8932.6922
E28: =F28&G28 -> CHERI BUFFET 1.8X0.5X0.83 - Acabamentos CustomizadosTampo: Mármore ou Porcelana Especial Corpo: Laca ou Lamina | F28: CHERI BUFFET 1.8X0.5X0.83 - Acabamentos Customizados | G28: Tampo: Mármore ou Porcelana Especial Corpo: Laca ou Lamina | H28: 14027.899 | N28: 9500.3255 | P28: #N/A | S28: 11185.755 | T28: =IF(S28,S28*(1-0.05)) -> 10626.467 | U28: =IF(T28,T28/(1-0.07)) -> 11426.309 | V28: =U28*1.1663 -> 13326.504 | W28: =V28*1.05263157894 -> 14027.899
E29: =F29&G29 -> CHERI BUFFET 2.0X0.5X0.83 - Acabamentos CustomizadosTampo: Espelho Bronze, Fume, Prata, Vidro Fosco ou Clear Corpo: Laca ou Lamina | F29: CHERI BUFFET 2.0X0.5X0.83 - Acabamentos Customizados | G29: Tampo: Espelho Bronze, Fume, Prata, Vidro Fosco ou Clear Corpo: Laca ou Lamina | H29: 11379.7 | N29: 9503.5479 | P29: #N/A | S29: 9074.0982 | T29: =IF(S29,S29*(1-0.05)) -> 8620.3933 | U29: =IF(T29,T29/(1-0.07)) -> 9269.2401 | V29: =U29*1.1663 -> 10810.715 | W29: =V29*1.05263157894 -> 11379.7
E30: =F30&G30 -> CHERI BUFFET 2.0X0.5X0.83 - Acabamentos CustomizadosTampo: Laca ou Lamina com ou sem Vidro Normal Pintado Corpo: Laca ou Lamina | F30: CHERI BUFFET 2.0X0.5X0.83 - Acabamentos Customizados | G30: Tampo: Laca ou Lamina com ou sem Vidro Normal Pintado Corpo: Laca ou Lamina | H30: 9476.7646 | N30: 11645.905 | P30: #N/A | S30: 7556.7102 | T30: =IF(S30,S30*(1-0.05)) -> 7178.8747 | U30: =IF(T30,T30/(1-0.07)) -> 7719.2201 | V30: =U30*1.1663 -> 9002.9264 | W30: =V30*1.05263157894 -> 9476.7646
E31: =F31&G31 -> CHERI BUFFET 2.0X0.5X0.83 - Acabamentos CustomizadosTampo: Mármore ou Porcelana Especial Corpo: Laca ou Lamina | F31: CHERI BUFFET 2.0X0.5X0.83 - Acabamentos Customizados | G31: Tampo: Mármore ou Porcelana Especial Corpo: Laca ou Lamina | H31: 14927.515 | N31: 13588.556 | P31: #N/A | S31: 11903.103 | T31: =IF(S31,S31*(1-0.05)) -> 11307.948 | U31: =IF(T31,T31/(1-0.07)) -> 12159.084 | V31: =U31*1.1663 -> 14181.139 | W31: =V31*1.05263157894 -> 14927.515
E32: =F32&G32 -> CHERI BUFFET 2.2X0.5X0.83 - Acabamentos CustomizadosTampo: Espelho Bronze, Fume, Prata, Vidro Fosco ou Clear Corpo: Laca ou Lamina | F32: CHERI BUFFET 2.2X0.5X0.83 - Acabamentos Customizados | G32: Tampo: Espelho Bronze, Fume, Prata, Vidro Fosco ou Clear Corpo: Laca ou Lamina | H32: 11711.285 | S32: 9338.502 | T32: =IF(S32,S32*(1-0.05)) -> 8871.5769 | U32: =IF(T32,T32/(1-0.07)) -> 9539.33 | V32: =U32*1.1663 -> 11125.721 | W32: =V32*1.05263157894 -> 11711.285
E33: =F33&G33 -> CHERI BUFFET 2.2X0.5X0.83 - Acabamentos CustomizadosTampo: Laca ou Lamina com ou sem Vidro Normal Pintado Corpo: Laca ou Lamina | F33: CHERI BUFFET 2.2X0.5X0.83 - Acabamentos Customizados | G33: Tampo: Laca ou Lamina com ou sem Vidro Normal Pintado Corpo: Laca ou Lamina | H33: 10307.887 | S33: 8219.4418 | T33: =IF(S33,S33*(1-0.05)) -> 7808.4697 | U33: =IF(T33,T33/(1-0.07)) -> 8396.204 | V33: =U33*1.1663 -> 9792.4927 | W33: =V33*1.05263157894 -> 10307.887
E34: =F34&G34 -> CHERI BUFFET 2.2X0.5X0.83 - Acabamentos CustomizadosTampo: Mármore ou Porcelana Especial Corpo: Laca ou Lamina | F34: CHERI BUFFET 2.2X0.5X0.83 - Acabamentos Customizados | G34: Tampo: Mármore ou Porcelana Especial Corpo: Laca ou Lamina | H34: 16386.479 | S34: 13066.472 | T34: =IF(S34,S34*(1-0.05)) -> 12413.148 | U34: =IF(T34,T34/(1-0.07)) -> 13347.471 | V34: =U34*1.1663 -> 15567.155 | W34: =V34*1.05263157894 -> 16386.479
E35: =F35&G35 -> CHERI BUFFET 2.4X0.5X0.83 - Acabamentos CustomizadosTampo: Espelho Bronze, Fume, Prata, Vidro Fosco ou Clear Corpo: Laca ou Lamina | F35: CHERI BUFFET 2.4X0.5X0.83 - Acabamentos Customizados | G35: Tampo: Espelho Bronze, Fume, Prata, Vidro Fosco ou Clear Corpo: Laca ou Lamina | H35: 12514.428 | S35: 9978.9231 | T35: =IF(S35,S35*(1-0.05)) -> 9479.9769 | U35: =IF(T35,T35/(1-0.07)) -> 10193.524 | V35: =U35*1.1663 -> 11888.707 | W35: =V35*1.05263157894 -> 12514.428
E36: =F36&G36 -> CHERI BUFFET 2.4X0.5X0.83 - Acabamentos CustomizadosTampo: Laca ou Lamina com ou sem Vidro Normal Pintado Corpo: Laca ou Lamina | F36: CHERI BUFFET 2.4X0.5X0.83 - Acabamentos Customizados | G36: Tampo: Laca ou Lamina com ou sem Vidro Normal Pintado Corpo: Laca ou Lamina | H36: 10927.274 | S36: 8713.3365 | T36: =IF(S36,S36*(1-0.05)) -> 8277.6697 | U36: =IF(T36,T36/(1-0.07)) -> 8900.7201 | V36: =U36*1.1663 -> 10380.91 | W36: =V36*1.05263157894 -> 10927.274
E37: =F37&G37 -> CHERI BUFFET 2.4X0.5X0.83 - Acabamentos CustomizadosTampo: Mármore ou Porcelana Especial Corpo: Laca ou Lamina | F37: CHERI BUFFET 2.4X0.5X0.83 - Acabamentos Customizados | G37: Tampo: Mármore ou Porcelana Especial Corpo: Laca ou Lamina | H37: 17634.757 | S37: 14061.84 | T37: =IF(S37,S37*(1-0.05)) -> 13358.748 | U37: =IF(T37,T37/(1-0.07)) -> 14364.245 | V37: =U37*1.1663 -> 16753.019 | W37: =V37*1.05263157894 -> 17634.757
E38: =F38&G38 -> YOKO BUFFET 1.2X0.55X0.755 - Acabamentos CustomizadosTampo: Espelho Bronze, Fume, Prata, Vidro Fosco ou Clear Corpo: Laca ou Lamina | F38: YOKO BUFFET 1.2X0.55X0.755 - Acabamentos Customizados | G38: Tampo: Espelho Bronze, Fume, Prata, Vidro Fosco ou Clear Corpo: Laca ou Lamina | H38: 7703.4635 | N38: 5361.8429 | P38: #N/A | S38: 6142.6915 | T38: =IF(S38,S38*(1-0.05)) -> 5835.5569 | U38: =IF(T38,T38/(1-0.07)) -> 6274.7924 | V38: =U38*1.1663 -> 7318.2904 | W38: =V38*1.05263157894 -> 7703.4635
E39: =F39&G39 -> YOKO BUFFET 1.2X0.55X0.755 - Acabamentos CustomizadosTampo: Laca ou Lamina com ou sem Vidro Normal Pintado Corpo: Laca ou Lamina | F39: YOKO BUFFET 1.2X0.55X0.755 - Acabamentos Customizados | G39: Tampo: Laca ou Lamina com ou sem Vidro Normal Pintado Corpo: Laca ou Lamina | H39: 6687.229 | N39: 6128.6622 | P39: #N/A | S39: 5332.3527 | T39: =IF(S39,S39*(1-0.05)) -> 5065.7351 | U39: =IF(T39,T39/(1-0.07)) -> 5447.027 | V39: =U39*1.1663 -> 6352.8676 | W39: =V39*1.05263157894 -> 6687.229
E40: =F40&G40 -> YOKO BUFFET 1.2X0.55X0.755 - Acabamentos CustomizadosTampo: Mármore ou Porcelana Especial Corpo: Laca ou Lamina | F40: YOKO BUFFET 1.2X0.55X0.755 - Acabamentos Customizados | G40: Tampo: Mármore ou Porcelana Especial Corpo: Laca ou Lamina | H40: 10038.514 | N40: 7019.8954 | P40: #N/A | S40: 8004.6458 | T40: =IF(S40,S40*(1-0.05)) -> 7604.4135 | U40: =IF(T40,T40/(1-0.07)) -> 8176.7887 | V40: =U40*1.1663 -> 9536.5887 | W40: =V40*1.05263157894 -> 10038.514
...

Sheet ESPELHO
B1: TABELA DE PREÇO CENTURY | MADEIRA
C5: Dimensoes (metros)
A6: Imagem | B6: Nome | C6: C | D6: L | E6: A | F6: Laca ou Lamina - Espelho Prata | G6: Laca ou Lamina - Espelho Bronze ou Fume | H6: Recoro - Espelho Prata | I6: Recoro - Espelho Bronze ou Fume
B7: Avant Espelho 1.84X0.1X1.91 - Acabamentos Customizados | C7: 1.84 | D7: 0.1 | E7: 1.91 | F7: =IFERROR(IF('BASE DE DADOS PREÇOS'!$M$71="com",VLOOKUP(CONCATENATE(B7,$F$6),'BASE DE DADOS PREÇOS'!$E:$H,4,0)/(1-SUM($G$1))*VLOOKUP(CAPA!$B$12,'POLITICA DE PREÇO'!#REF!,2,0)*0.95,VLOOKUP(CONCATENATE(B7,$F$6),'BASE DE DADOS PREÇOS'!$E:$H,4,0)/(1-SUM($G$1))*VLOOKUP(CAPA!$B$12,'POLITICA DE PREÇO'!$B$4:$F$100,5,0))*CAPA!$B$14,"") -> 3530.3932 | G7: =IFERROR(IF('BASE DE DADOS PREÇOS'!$M$71="com",VLOOKUP(CONCATENATE(B7,$G$6),'BASE DE DADOS PREÇOS'!$E:$H,4,0)/(1-SUM($G$1))*VLOOKUP(CAPA!$B$12,'POLITICA DE PREÇO'!#REF!,2,0)*0.95,VLOOKUP(CONCATENATE(B7,$G$6),'BASE DE DADOS PREÇOS'!$E:$H,4,0)/(1-SUM($G$1))*VLOOKUP(CAPA!$B$12,'POLITICA DE PREÇO'!$B$4:$F$100,5,0))*CAPA!$B$14,"") -> 6052.1026
B8: Ettore Espelho 2.05X0.14X1.95 - Acabamentos Customizados | C8: 2.05 | D8: 0.14 | E8: 1.95 | F8: =IFERROR(IF('BASE DE DADOS PREÇOS'!$M$71="com",VLOOKUP(CONCATENATE(B8,$F$6),'BASE DE DADOS PREÇOS'!$E:$H,4,0)/(1-SUM($G$1))*VLOOKUP(CAPA!$B$12,'POLITICA DE PREÇO'!#REF!,2,0)*0.95,VLOOKUP(CONCATENATE(B8,$F$6),'BASE DE DADOS PREÇOS'!$E:$H,4,0)/(1-SUM($G$1))*VLOOKUP(CAPA!$B$12,'POLITICA DE PREÇO'!$B$4:$F$100,5,0))*CAPA!$B$14,"") -> 3691.8218 | G8: =IFERROR(IF('BASE DE DADOS PREÇOS'!$M$71="com",VLOOKUP(CONCATENATE(B8,$G$6),'BASE DE DADOS PREÇOS'!$E:$H,4,0)/(1-SUM($G$1))*VLOOKUP(CAPA!$B$12,'POLITICA DE PREÇO'!#REF!,2,0)*0.95,VLOOKUP(CONCATENATE(B8,$G$6),'BASE DE DADOS PREÇOS'!$E:$H,4,0)/(1-SUM($G$1))*VLOOKUP(CAPA!$B$12,'POLITICA DE PREÇO'!$B$4:$F$100,5,0))*CAPA!$B$14,"") -> 6328.8374 | H8: =F8*1.05 -> 3876.4129 | I8: =G8*1.05 -> 6645.2792

Sheet POLITICA DE PREÇO
B2: PRAZO DE PAGAMENTO | C2: PRAZO MÉDIO | D2: DESCONTOS | E2: Coefic. (%) | F2: Coef. Desc
D3: Desc. 1
B4: 15 DIAS - OURO | C4: 15 DIAS | D4: 0.1425 | E4: 0.1425 | F4: =(1-E4) -> 0.8575
B5: 30 DIAS - OURO | C5: 30 DIAS | D5: 0.1325 | E5: 0.1325 | F5: =(1-E5) -> 0.8675
B6: 45 DIAS - OURO | C6: 45 DIAS | D6: 0.12 | E6: 0.12 | F6: =(1-E6) -> 0.88
B7: 60 DIAS - OURO | C7: 60 DIAS | D7: 0.1075 | E7: 0.1075 | F7: =(1-E7) -> 0.8925
B8: 75 DIAS - OURO | C8: 75 DIAS | D8: 0.09 | E8: 0.09 | F8: =(1-E8) -> 0.91
B9: 90 DIAS - OURO | C9: 90 DIAS | D9: 0.0725 | E9: 0.0725 | F9: =(1-E9) -> 0.9275
B10: 105 DIAS - OURO | C10: 105 DIAS | D10: 0.055 | E10: 0.055 | F10: =(1-E10) -> 0.945
B11: 120 DIAS - OURO | C11: 120 DIAS | D11: 0.035 | E11: 0.035 | F11: =(1-E11) -> 0.965
B12: 135 DIAS - OURO | C12: 135 DIAS | D12: 0.01 | E12: 0.01 | F12: =(1-E12) -> 0.99
B13: 150 DIAS - OURO | C13: 150 DIAS | D13: -0.015 | E13: -0.015 | F13: =(1-E13) -> 1.015
B14: 165 DIAS - OURO | C14: 165 DIAS | D14: -0.04 | E14: -0.04 | F14: =(1-E14) -> 1.04
B15: 180 DIAS - OURO | C15: 180 DIAS | D15: -0.0675 | E15: -0.0675 | F15: =(1-E15) -> 1.0675

Sheet MESA DE CABECEIRA
B1: TABELA DE PREÇO CENTURY | MADEIRA
C5: Dimensoes (metros)
A6: Imagem | B6: Nome | C6: C | D6: L | E6: A | G6: Tampo: Espelho Bronze, Fume, Prata, Vidro Fosco ou Clear Corpo: Laca ou Lamina | H6: Tampo: Laca ou Lamina com ou sem Vidro Normal Pintado Corpo: Laca ou Lamina | I6: Tampo: Mármore Especial Corpo: Laca ou Lamina | J6: Tampo: Mármore Normal Corpo: Laca ou Lamina | K6: Tampo ou Base em Recoro
B7: Barcelona Mesa de Cabeceira - Øx0.5x0.530 - Acabamentos Customizados | C7: Ø | D7: 0.5 | E7: 0.53 | G7: =IFERROR(IF('BASE DE DADOS PREÇOS'!$M$71="com",VLOOKUP(CONCATENATE(B7,$G$6),'BASE DE DADOS PREÇOS'!$E:$H,4,0)/(1-SUM($F$1))*VLOOKUP(CAPA!$B$12,'POLITICA DE PREÇO'!#REF!,2,0)*0.95,VLOOKUP(CONCATENATE(B7,$G$6),'BASE DE DADOS PREÇOS'!$E:$H,4,0)/(1-SUM($F$1))*VLOOKUP(CAPA!$B$12,'POLITICA DE PREÇO'!$B$4:$F$100,5,0))*CAPA!$B$14,"") -> 3253.0323 | H7: =IFERROR(IF('BASE DE DADOS PREÇOS'!$M$71="com",VLOOKUP(CONCATENATE(B7,$H$6),'BASE DE DADOS PREÇOS'!$E:$H,4,0)/(1-SUM($F$1))*VLOOKUP(CAPA!$B$12,'POLITICA DE PREÇO'!#REF!,2,0)*0.95,VLOOKUP(CONCATENATE(B7,$H$6),'BASE DE DADOS PREÇOS'!$E:$H,4,0)/(1-SUM($F$1))*VLOOKUP(CAPA!$B$12,'POLITICA DE PREÇO'!$B$4:$F$100,5,0))*CAPA!$B$14,"") -> 3083.3804 | I7: =IFERROR(IF('BASE DE DADOS PREÇOS'!$M$71="com",VLOOKUP(CONCATENATE(B7,$I$6),'BASE DE DADOS PREÇOS'!$E:$H,4,0)/(1-SUM($F$1))*VLOOKUP(CAPA!$B$12,'POLITICA DE PREÇO'!#REF!,2,0)*0.95,VLOOKUP(CONCATENATE(B7,$I$6),'BASE DE DADOS PREÇOS'!$E:$H,4,0)/(1-SUM($F$1))*VLOOKUP(CAPA!$B$12,'POLITICA DE PREÇO'!$B$4:$F$100,5,0))*CAPA!$B$14,"") -> 4087.7868 | J7: =I7*0.9 -> 3679.0081 | K7: =H7*1.05 -> 3237.5495
B8: Cayman Mesa de Cabeceira 0.7X0.45X0.53 - Acabamentos Customizados | C8: 0.7 | D8: 0.45 | E8: 0.53 | G8: =IFERROR(IF('BASE DE DADOS PREÇOS'!$M$71="com",VLOOKUP(CONCATENATE(B8,$G$6),'BASE DE DADOS PREÇOS'!$E:$H,4,0)/(1-SUM($F$1))*VLOOKUP(CAPA!$B$12,'POLITICA DE PREÇO'!#REF!,2,0)*0.95,VLOOKUP(CONCATENATE(B8,$G$6),'BASE DE DADOS PREÇOS'!$E:$H,4,0)/(1-SUM($F$1))*VLOOKUP(CAPA!$B$12,'POLITICA DE PREÇO'!$B$4:$F$100,5,0))*CAPA!$B$14,"") -> 3747.1793 | H8: =IFERROR(IF('BASE DE DADOS PREÇOS'!$M$71="com",VLOOKUP(CONCATENATE(B8,$H$6),'BASE DE DADOS PREÇOS'!$E:$H,4,0)/(1-SUM($F$1))*VLOOKUP(CAPA!$B$12,'POLITICA DE PREÇO'!#REF!,2,0)*0.95,VLOOKUP(CONCATENATE(B8,$H$6),'BASE DE DADOS PREÇOS'!$E:$H,4,0)/(1-SUM($F$1))*VLOOKUP(CAPA!$B$12,'POLITICA DE PREÇO'!$B$4:$F$100,5,0))*CAPA!$B$14,"") -> 3645.1765 | I8: =IFERROR(IF('BASE DE DADOS PREÇOS'!$M$71="com",VLOOKUP(CONCATENATE(B8,$I$6),'BASE DE DADOS PREÇOS'!$E:$H,4,0)/(1-SUM($F$1))*VLOOKUP(CAPA!$B$12,'POLITICA DE PREÇO'!#REF!,2,0)*0.95,VLOOKUP(CONCATENATE(B8,$I$6),'BASE DE DADOS PREÇOS'!$E:$H,4,0)/(1-SUM($F$1))*VLOOKUP(CAPA!$B$12,'POLITICA DE PREÇO'!$B$4:$F$100,5,0))*CAPA!$B$14,"") -> 4821.2372 | J8: =I8*0.9 -> 4339.1135 | K8: =H8*1.05 -> 3827.4353
B9: Cayman Mesa de Cabeceira 0.8X0.45X0.53 - Acabamentos Customizados | C9: 0.8 | D9: 0.45 | E9: 0.53 | G9: =IFERROR(IF('BASE DE DADOS PREÇOS'!$M$71="com",VLOOKUP(CONCATENATE(B9,$G$6),'BASE DE DADOS PREÇOS'!$E:$H,4,0)/(1-SUM($F$1))*VLOOKUP(CAPA!$B$12,'POLITICA DE PREÇO'!#REF!,2,0)*0.95,VLOOKUP(CONCATENATE(B9,$G$6),'BASE DE DADOS PREÇOS'!$E:$H,4,0)/(1-SUM($F$1))*VLOOKUP(CAPA!$B$12,'POLITICA DE PREÇO'!$B$4:$F$100,5,0))*CAPA!$B$14,"") -> 3999.5335 | H9: =IFERROR(IF('BASE DE DADOS PREÇOS'!$M$71="com",VLOOKUP(CONCATENATE(B9,$H$6),'BASE DE DADOS PREÇOS'!$E:$H,4,0)/(1-SUM($F$1))*VLOOKUP(CAPA!$B$12,'POLITICA DE PREÇO'!#REF!,2,0)*0.95,VLOOKUP(CONCATENATE(B9,$H$6),'BASE DE DADOS PREÇOS'!$E:$H,4,0)/(1-SUM($F$1))*VLOOKUP(CAPA!$B$12,'POLITICA DE PREÇO'!$B$4:$F$100,5,0))*CAPA!$B$14,"") -> 3833.642 | I9: =IFERROR(IF('BASE DE DADOS PREÇOS'!$M$71="com",VLOOKUP(CONCATENATE(B9,$I$6),'BASE DE DADOS PREÇOS'!$E:$H,4,0)/(1-SUM($F$1))*VLOOKUP(CAPA!$B$12,'POLITICA DE PREÇO'!#REF!,2,0)*0.95,VLOOKUP(CONCATENATE(B9,$I$6),'BASE DE DADOS PREÇOS'!$E:$H,4,0)/(1-SUM($F$1))*VLOOKUP(CAPA!$B$12,'POLITICA DE PREÇO'!$B$4:$F$100,5,0))*CAPA!$B$14,"") -> 5209.6803 | J9: =I9*0.9 -> 4688.7123 | K9: =H9*1.05 -> 4025.3241
B10: Cayman Mesa de Cabeceira 0.9X0.45X0.53 - Acabamentos Customizados | C10: 0.9 | D10: 0.45 | E10: 0.53 | G10: =IFERROR(IF('BASE DE DADOS PREÇOS'!$M$71="com",VLOOKUP(CONCATENATE(B10,$G$6),'BASE DE DADOS PREÇOS'!$E:$H,4,0)/(1-SUM($F$1))*VLOOKUP(CAPA!$B$12,'POLITICA DE PREÇO'!#REF!,2,0)*0.95,VLOOKUP(CONCATENATE(B10,$G$6),'BASE DE DADOS PREÇOS'!$E:$H,4,0)/(1-SUM($F$1))*VLOOKUP(CAPA!$B$12,'POLITICA DE PREÇO'!$B$4:$F$100,5,0))*CAPA!$B$14,"") -> 4323.2984 | H10: =IFERROR(IF('BASE DE DADOS PREÇOS'!$M$71="com",VLOOKUP(CONCATENATE(B10,$H$6),'BASE DE DADOS PREÇOS'!$E:$H,4,0)/(1-SUM($F$1))*VLOOKUP(CAPA!$B$12,'POLITICA DE PREÇO'!#REF!,2,0)*0.95,VLOOKUP(CONCATENATE(B10,$H$6),'BASE DE DADOS PREÇOS'!$E:$H,4,0)/(1-SUM($F$1))*VLOOKUP(CAPA!$B$12,'POLITICA DE PREÇO'!$B$4:$F$100,5,0))*CAPA!$B$14,"") -> 4045.3673 | I10: =IFERROR(IF('BASE DE DADOS PREÇOS'!$M$71="com",VLOOKUP(CONCATENATE(B10,$I$6),'BASE DE DADOS PREÇOS'!$E:$H,4,0)/(1-SUM($F$1))*VLOOKUP(CAPA!$B$12,'POLITICA DE PREÇO'!#REF!,2,0)*0.95,VLOOKUP(CONCATENATE(B10,$I$6),'BASE DE DADOS PREÇOS'!$E:$H,4,0)/(1-SUM($F$1))*VLOOKUP(CAPA!$B$12,'POLITICA DE PREÇO'!$B$4:$F$100,5,0))*CAPA!$B$14,"") -> 5381.7698 | J10: =I10*0.9 -> 4843.5928 | K10: =H10*1.05 -> 4247.6356
B11: Cayman Mesa de Cabeceira 1X0.45X0.53 - Acabamentos Customizados | C11: 1 | D11: 0.45 | E11: 0.53 | G11: =IFERROR(IF('BASE DE DADOS PREÇOS'!$M$71="com",VLOOKUP(CONCATENATE(B11,$G$6),'BASE DE DADOS PREÇOS'!$E:$H,4,0)/(1-SUM($F$1))*VLOOKUP(CAPA!$B$12,'POLITICA DE PREÇO'!#REF!,2,0)*0.95,VLOOKUP(CONCATENATE(B11,$G$6),'BASE DE DADOS PREÇOS'!$E:$H,4,0)/(1-SUM($F$1))*VLOOKUP(CAPA!$B$12,'POLITICA DE PREÇO'!$B$4:$F$100,5,0))*CAPA!$B$14,"") -> 4598.2763 | H11: =IFERROR(IF('BASE DE DADOS PREÇOS'!$M$71="com",VLOOKUP(CONCATENATE(B11,$H$6),'BASE DE DADOS PREÇOS'!$E:$H,4,0)/(1-SUM($F$1))*VLOOKUP(CAPA!$B$12,'POLITICA DE PREÇO'!#REF!,2,0)*0.95,VLOOKUP(CONCATENATE(B11,$H$6),'BASE DE DADOS PREÇOS'!$E:$H,4,0)/(1-SUM($F$1))*VLOOKUP(CAPA!$B$12,'POLITICA DE PREÇO'!$B$4:$F$100,5,0))*CAPA!$B$14,"") -> 4290.8689 | I11: =IFERROR(IF('BASE DE DADOS PREÇOS'!$M$71="com",VLOOKUP(CONCATENATE(B11,$I$6),'BASE DE DADOS PREÇOS'!$E:$H,4,0)/(1-SUM($F$1))*VLOOKUP(CAPA!$B$12,'POLITICA DE PREÇO'!#REF!,2,0)*0.95,VLOOKUP(CONCATENATE(B11,$I$6),'BASE DE DADOS PREÇOS'!$E:$H,4,0)/(1-SUM($F$1))*VLOOKUP(CAPA!$B$12,'POLITICA DE PREÇO'!$B$4:$F$100,5,0))*CAPA!$B$14,"") -> 6075.1001 | J11: =I11*0.9 -> 5467.5901 | K11: =H11*1.05 -> 4505.4124
B12: Stare Mesa de Cabeceira 0.7X0.45X0.53 - Acabamentos Customizados | C12: 0.7 | D12: 0.45 | E12: 0.53 | G12: =IFERROR(IF('BASE DE DADOS PREÇOS'!$M$71="com",VLOOKUP(CONCATENATE(B12,$G$6),'BASE DE DADOS PREÇOS'!$E:$H,4,0)/(1-SUM($F$1))*VLOOKUP(CAPA!$B$12,'POLITICA DE PREÇO'!#REF!,2,0)*0.95,VLOOKUP(CONCATENATE(B12,$G$6),'BASE DE DADOS PREÇOS'!$E:$H,4,0)/(1-SUM($F$1))*VLOOKUP(CAPA!$B$12,'POLITICA DE PREÇO'!$B$4:$F$100,5,0))*CAPA!$B$14,"") -> 3603.057 | H12: =IFERROR(IF('BASE DE DADOS PREÇOS'!$M$71="com",VLOOKUP(CONCATENATE(B12,$H$6),'BASE DE DADOS PREÇOS'!$E:$H,4,0)/(1-SUM($F$1))*VLOOKUP(CAPA!$B$12,'POLITICA DE PREÇO'!#REF!,2,0)*0.95,VLOOKUP(CONCATENATE(B12,$H$6),'BASE DE DADOS PREÇOS'!$E:$H,4,0)/(1-SUM($F$1))*VLOOKUP(CAPA!$B$12,'POLITICA DE PREÇO'!$B$4:$F$100,5,0))*CAPA!$B$14,"") -> 3504.9774 | I12: =IFERROR(IF('BASE DE DADOS PREÇOS'!$M$71="com",VLOOKUP(CONCATENATE(B12,$I$6),'BASE DE DADOS PREÇOS'!$E:$H,4,0)/(1-SUM($F$1))*VLOOKUP(CAPA!$B$12,'POLITICA DE PREÇO'!#REF!,2,0)*0.95,VLOOKUP(CONCATENATE(B12,$I$6),'BASE DE DADOS PREÇOS'!$E:$H,4,0)/(1-SUM($F$1))*VLOOKUP(CAPA!$B$12,'POLITICA DE PREÇO'!$B$4:$F$100,5,0))*CAPA!$B$14,"") -> 4635.805 | J12: =I12*0.9 -> 4172.2245 | K12: =H12*1.05 -> 3680.2263
B13: Stare Mesa de Cabeceira 0.8X0.45X0.53 - Acabamentos Customizados | C13: 0.8 | D13: 0.45 | E13: 0.53 | G13: =IFERROR(IF('BASE DE DADOS PREÇOS'!$M$71="com",VLOOKUP(CONCATENATE(B13,$G$6),'BASE DE DADOS PREÇOS'!$E:$H,4,0)/(1-SUM($F$1))*VLOOKUP(CAPA!$B$12,'POLITICA DE PREÇO'!#REF!,2,0)*0.95,VLOOKUP(CONCATENATE(B13,$G$6),'BASE DE DADOS PREÇOS'!$E:$H,4,0)/(1-SUM($F$1))*VLOOKUP(CAPA!$B$12,'POLITICA DE PREÇO'!$B$4:$F$100,5,0))*CAPA!$B$14,"") -> 3845.7053 | H13: =IFERROR(IF('BASE DE DADOS PREÇOS'!$M$71="com",VLOOKUP(CONCATENATE(B13,$H$6),'BASE DE DADOS PREÇOS'!$E:$H,4,0)/(1-SUM($F$1))*VLOOKUP(CAPA!$B$12,'POLITICA DE PREÇO'!#REF!,2,0)*0.95,VLOOKUP(CONCATENATE(B13,$H$6),'BASE DE DADOS PREÇOS'!$E:$H,4,0)/(1-SUM($F$1))*VLOOKUP(CAPA!$B$12,'POLITICA DE PREÇO'!$B$4:$F$100,5,0))*CAPA!$B$14,"") -> 3592.4774 | I13: =IFERROR(IF('BASE DE DADOS PREÇOS'!$M$71="com",VLOOKUP(CONCATENATE(B13,$I$6),'BASE DE DADOS PREÇOS'!$E:$H,4,0)/(1-SUM($F$1))*VLOOKUP(CAPA!$B$12,'POLITICA DE PREÇO'!#REF!,2,0)*0.95,VLOOKUP(CONCATENATE(B13,$I$6),'BASE DE DADOS PREÇOS'!$E:$H,4,0)/(1-SUM($F$1))*VLOOKUP(CAPA!$B$12,'POLITICA DE PREÇO'!$B$4:$F$100,5,0))*CAPA!$B$14,"") -> 5009.308 | J13: =I13*0.9 -> 4508.3772 | K13: =H13*1.05 -> 3772.1013
B14: Stare Mesa de Cabeceira 0.9X0.45X0.53 - Acabamentos Customizados | C14: 0.9 | D14: 0.45 | E14: 0.53 | G14: =IFERROR(IF('BASE DE DADOS PREÇOS'!$M$71="com",VLOOKUP(CONCATENATE(B14,$G$6),'BASE DE DADOS PREÇOS'!$E:$H,4,0)/(1-SUM($F$1))*VLOOKUP(CAPA!$B$12,'POLITICA DE PREÇO'!#REF!,2,0)*0.95,VLOOKUP(CONCATENATE(B14,$G$6),'BASE DE DADOS PREÇOS'!$E:$H,4,0)/(1-SUM($F$1))*VLOOKUP(CAPA!$B$12,'POLITICA DE PREÇO'!$B$4:$F$100,5,0))*CAPA!$B$14,"") -> 4157.0177 | H14: =IFERROR(IF('BASE DE DADOS PREÇOS'!$M$71="com",VLOOKUP(CONCATENATE(B14,$H$6),'BASE DE DADOS PREÇOS'!$E:$H,4,0)/(1-SUM($F$1))*VLOOKUP(CAPA!$B$12,'POLITICA DE PREÇO'!#REF!,2,0)*0.95,VLOOKUP(CONCATENATE(B14,$H$6),'BASE DE DADOS PREÇOS'!$E:$H,4,0)/(1-SUM($F$1))*VLOOKUP(CAPA!$B$12,'POLITICA DE PREÇO'!$B$4:$F$100,5,0))*CAPA!$B$14,"") -> 3889.7762 | I14: =IFERROR(IF('BASE DE DADOS PREÇOS'!$M$71="com",VLOOKUP(CONCATENATE(B14,$I$6),'BASE DE DADOS PREÇOS'!$E:$H,4,0)/(1-SUM($F$1))*VLOOKUP(CAPA!$B$12,'POLITICA DE PREÇO'!#REF!,2,0)*0.95,VLOOKUP(CONCATENATE(B14,$I$6),'BASE DE DADOS PREÇOS'!$E:$H,4,0)/(1-SUM($F$1))*VLOOKUP(CAPA!$B$12,'POLITICA DE PREÇO'!$B$4:$F$100,5,0))*CAPA!$B$14,"") -> 5409.9959 | J14: =I14*0.9 -> 4868.9963 | K14: =H14*1.05 -> 4084.265
B15: Stare Mesa de Cabeceira 1X0.45X0.53 - Acabamentos Customizados | C15: 1 | D15: 0.45 | E15: 0.53 | G15: =IFERROR(IF('BASE DE DADOS PREÇOS'!$M$71="com",VLOOKUP(CONCATENATE(B15,$G$6),'BASE DE DADOS PREÇOS'!$E:$H,4,0)/(1-SUM($F$1))*VLOOKUP(CAPA!$B$12,'POLITICA DE PREÇO'!#REF!,2,0)*0.95,VLOOKUP(CONCATENATE(B15,$G$6),'BASE DE DADOS PREÇOS'!$E:$H,4,0)/(1-SUM($F$1))*VLOOKUP(CAPA!$B$12,'POLITICA DE PREÇO'!$B$4:$F$100,5,0))*CAPA!$B$14,"") -> 4421.4195 | H15: =IFERROR(IF('BASE DE DADOS PREÇOS'!$M$71="com",VLOOKUP(CONCATENATE(B15,$H$6),'BASE DE DADOS PREÇOS'!$E:$H,4,0)/(1-SUM($F$1))*VLOOKUP(CAPA!$B$12,'POLITICA DE PREÇO'!#REF!,2,0)*0.95,VLOOKUP(CONCATENATE(B15,$H$6),'BASE DE DADOS PREÇOS'!$E:$H,4,0)/(1-SUM($F$1))*VLOOKUP(CAPA!$B$12,'POLITICA DE PREÇO'!$B$4:$F$100,5,0))*CAPA!$B$14,"") -> 3938.2975 | I15: =IFERROR(IF('BASE DE DADOS PREÇOS'!$M$71="com",VLOOKUP(CONCATENATE(B15,$I$6),'BASE DE DADOS PREÇOS'!$E:$H,4,0)/(1-SUM($F$1))*VLOOKUP(CAPA!$B$12,'POLITICA DE PREÇO'!#REF!,2,0)*0.95,VLOOKUP(CONCATENATE(B15,$I$6),'BASE DE DADOS PREÇOS'!$E:$H,4,0)/(1-SUM($F$1))*VLOOKUP(CAPA!$B$12,'POLITICA DE PREÇO'!$B$4:$F$100,5,0))*CAPA!$B$14,"") -> 5841.4424 | J15: =I15*0.9 -> 5257.2981 | K15: =H15*1.05 -> 4135.2124
B16: Turin Mesa de Cabeceira - 2 Gavetas - 0.6x0.45x0.53 - Acabamentos Customizados | C16: 0.6 | D16: 0.45 | E16: 0.53 | G16: =IFERROR(IF('BASE DE DADOS PREÇOS'!$M$71="com",VLOOKUP(CONCATENATE(B16,$G$6),'BASE DE DADOS PREÇOS'!$E:$H,4,0)/(1-SUM($F$1))*VLOOKUP(CAPA!$B$12,'POLITICA DE PREÇO'!#REF!,2,0)*0.95,VLOOKUP(CONCATENATE(B16,$G$6),'BASE DE DADOS PREÇOS'!$E:$H,4,0)/(1-SUM($F$1))*VLOOKUP(CAPA!$B$12,'POLITICA DE PREÇO'!$B$4:$F$100,5,0))*CAPA!$B$14,"") -> 3237.7186 | H16: =IFERROR(IF('BASE DE DADOS PREÇOS'!$M$71="com",VLOOKUP(CONCATENATE(B16,$H$6),'BASE DE DADOS PREÇOS'!$E:$H,4,0)/(1-SUM($F$1))*VLOOKUP(CAPA!$B$12,'POLITICA DE PREÇO'!#REF!,2,0)*0.95,VLOOKUP(CONCATENATE(B16,$H$6),'BASE DE DADOS PREÇOS'!$E:$H,4,0)/(1-SUM($F$1))*VLOOKUP(CAPA!$B$12,'POLITICA DE PREÇO'!$B$4:$F$100,5,0))*CAPA!$B$14,"") -> 3039.0139 | I16: =IFERROR(IF('BASE DE DADOS PREÇOS'!$M$71="com",VLOOKUP(CONCATENATE(B16,$I$6),'BASE DE DADOS PREÇOS'!$E:$H,4,0)/(1-SUM($F$1))*VLOOKUP(CAPA!$B$12,'POLITICA DE PREÇO'!#REF!,2,0)*0.95,VLOOKUP(CONCATENATE(B16,$I$6),'BASE DE DADOS PREÇOS'!$E:$H,4,0)/(1-SUM($F$1))*VLOOKUP(CAPA!$B$12,'POLITICA DE PREÇO'!$B$4:$F$100,5,0))*CAPA!$B$14,"") -> 4150.0273 | J16: =I16*0.9 -> 3735.0245 | K16: =H16*1.05 -> 3190.9646
